
[notice] A new release of pip is available: 24.0 -> 24.2
[notice] To update, run: python.exe -m pip install --upgrade pip
  Running command git clone --filter=blob:none --quiet https://github.com/openai/whisper.git 'C:\Users\drakkka\AppData\Local\Temp\pip-req-build-fe5n6g44'

[notice] A new release of pip is available: 24.0 -> 24.2
[notice] To update, run: python.exe -m pip install --upgrade pip

[notice] A new release of pip is available: 24.0 -> 24.2
[notice] To update, run: python.exe -m pip install --upgrade pip
[2024-10-31 00:07:00] [INFO    ] discord.client: logging in using static token
[2024-10-31 00:07:01] [INFO    ] discord.gateway: Shard ID None has connected to Gateway (Session ID: 49ac14ee2d4b1eb5408d2bddfa79aae8).
Exception in thread Thread-6 (run_vtube_studio_connection):
Traceback (most recent call last):
  File "C:\Users\drakkka\python\Lib\threading.py", line 1045, in _bootstrap_inner
    self.run()
  File "C:\Users\drakkka\python\Lib\threading.py", line 982, in run
    self._target(*self._args, **self._kwargs)
  File "C:\Users\drakkka\Documents\tuber stuff\aigohere\zwaif\z-waif-main\z-waif main new\utils\vtube_studio.py", line 50, in run_vtube_studio_connection
    asyncio.run(vtube_studio_connection())
  File "C:\Users\drakkka\python\Lib\asyncio\runners.py", line 190, in run
    return runner.run(main)
           ^^^^^^^^^^^^^^^^
  File "C:\Users\drakkka\python\Lib\asyncio\runners.py", line 118, in run
    return self._loop.run_until_complete(task)
           ^^^^^^^^^^^^^^^^^^^^^^^^^^^^^^^^^^^
  File "C:\Users\drakkka\python\Lib\asyncio\base_events.py", line 654, in run_until_complete
    return future.result()
           ^^^^^^^^^^^^^^^
  File "C:\Users\drakkka\Documents\tuber stuff\aigohere\zwaif\z-waif-main\z-waif main new\utils\vtube_studio.py", line 53, in vtube_studio_connection
    await VTS.connect()
  File "C:\Users\drakkka\Documents\tuber stuff\aigohere\zwaif\z-waif-main\z-waif main new\venv\Lib\site-packages\pyvts\vts.py", line 82, in connect
    self.websocket = await websockets.connect(
                     ^^^^^^^^^^^^^^^^^^^^^^^^^
  File "C:\Users\drakkka\Documents\tuber stuff\aigohere\zwaif\z-waif-main\z-waif main new\venv\Lib\site-packages\websockets\legacy\client.py", line 655, in __await_impl_timeout__
    return await self.__await_impl__()
           ^^^^^^^^^^^^^^^^^^^^^^^^^^^
  File "C:\Users\drakkka\Documents\tuber stuff\aigohere\zwaif\z-waif-main\z-waif main new\venv\Lib\site-packages\websockets\legacy\client.py", line 659, in __await_impl__
    _transport, _protocol = await self._create_connection()
                            ^^^^^^^^^^^^^^^^^^^^^^^^^^^^^^^
  File "C:\Users\drakkka\python\Lib\asyncio\base_events.py", line 1091, in create_connection
    raise exceptions[0]
  File "C:\Users\drakkka\python\Lib\asyncio\base_events.py", line 1070, in create_connection
    sock = await self._connect_sock(
           ^^^^^^^^^^^^^^^^^^^^^^^^^
  File "C:\Users\drakkka\python\Lib\asyncio\base_events.py", line 974, in _connect_sock
    await self.sock_connect(sock, address)
  File "C:\Users\drakkka\python\Lib\asyncio\proactor_events.py", line 726, in sock_connect
    return await self._proactor.connect(sock, address)
           ^^^^^^^^^^^^^^^^^^^^^^^^^^^^^^^^^^^^^^^^^^^
  File "C:\Users\drakkka\python\Lib\asyncio\windows_events.py", line 854, in _poll
    value = callback(transferred, key, ov)
            ^^^^^^^^^^^^^^^^^^^^^^^^^^^^^^
  File "C:\Users\drakkka\python\Lib\asyncio\windows_events.py", line 641, in finish_connect
    ov.getresult()
ConnectionRefusedError: [WinError 1225] The remote computer refused the network connection
[2024-10-31 00:58:43] [INFO    ] discord.gateway: Shard ID None has successfully RESUMED session 49ac14ee2d4b1eb5408d2bddfa79aae8.
[2024-10-31 01:06:59] [INFO    ] discord.gateway: Shard ID None has successfully RESUMED session 49ac14ee2d4b1eb5408d2bddfa79aae8.
[2024-10-31 01:24:02] [INFO    ] discord.gateway: Shard ID None has successfully RESUMED session 49ac14ee2d4b1eb5408d2bddfa79aae8.
[2024-10-31 03:00:52] [INFO    ] discord.gateway: Shard ID None has successfully RESUMED session 49ac14ee2d4b1eb5408d2bddfa79aae8.
[2024-10-31 03:50:25] [INFO    ] discord.gateway: Shard ID None has successfully RESUMED session 49ac14ee2d4b1eb5408d2bddfa79aae8.
Exception in thread Thread-28 (check_emote_string):
Traceback (most recent call last):
  File "C:\Users\drakkka\python\Lib\threading.py", line 1045, in _bootstrap_inner
    self.run()
  File "C:\Users\drakkka\python\Lib\threading.py", line 982, in run
    self._target(*self._args, **self._kwargs)
  File "C:\Users\drakkka\Documents\tuber stuff\aigohere\zwaif\z-waif-main\z-waif main new\utils\vtube_studio.py", line 95, in check_emote_string
    run_emote()
  File "C:\Users\drakkka\Documents\tuber stuff\aigohere\zwaif\z-waif-main\z-waif main new\utils\vtube_studio.py", line 99, in run_emote
    asyncio.run(emote())
  File "C:\Users\drakkka\python\Lib\asyncio\runners.py", line 190, in run
    return runner.run(main)
           ^^^^^^^^^^^^^^^^
  File "C:\Users\drakkka\python\Lib\asyncio\runners.py", line 118, in run
    return self._loop.run_until_complete(task)
           ^^^^^^^^^^^^^^^^^^^^^^^^^^^^^^^^^^^
  File "C:\Users\drakkka\python\Lib\asyncio\base_events.py", line 654, in run_until_complete
    return future.result()
           ^^^^^^^^^^^^^^^
  File "C:\Users\drakkka\Documents\tuber stuff\aigohere\zwaif\z-waif-main\z-waif main new\utils\vtube_studio.py", line 102, in emote
    await VTS.connect()
  File "C:\Users\drakkka\Documents\tuber stuff\aigohere\zwaif\z-waif-main\z-waif main new\venv\Lib\site-packages\pyvts\vts.py", line 82, in connect
    self.websocket = await websockets.connect(
                     ^^^^^^^^^^^^^^^^^^^^^^^^^
  File "C:\Users\drakkka\Documents\tuber stuff\aigohere\zwaif\z-waif-main\z-waif main new\venv\Lib\site-packages\websockets\legacy\client.py", line 655, in __await_impl_timeout__
    return await self.__await_impl__()
           ^^^^^^^^^^^^^^^^^^^^^^^^^^^
  File "C:\Users\drakkka\Documents\tuber stuff\aigohere\zwaif\z-waif-main\z-waif main new\venv\Lib\site-packages\websockets\legacy\client.py", line 659, in __await_impl__
    _transport, _protocol = await self._create_connection()
                            ^^^^^^^^^^^^^^^^^^^^^^^^^^^^^^^
  File "C:\Users\drakkka\python\Lib\asyncio\base_events.py", line 1091, in create_connection
    raise exceptions[0]
  File "C:\Users\drakkka\python\Lib\asyncio\base_events.py", line 1070, in create_connection
    sock = await self._connect_sock(
           ^^^^^^^^^^^^^^^^^^^^^^^^^
  File "C:\Users\drakkka\python\Lib\asyncio\base_events.py", line 974, in _connect_sock
    await self.sock_connect(sock, address)
  File "C:\Users\drakkka\python\Lib\asyncio\proactor_events.py", line 726, in sock_connect
    return await self._proactor.connect(sock, address)
           ^^^^^^^^^^^^^^^^^^^^^^^^^^^^^^^^^^^^^^^^^^^
  File "C:\Users\drakkka\python\Lib\asyncio\windows_events.py", line 854, in _poll
    value = callback(transferred, key, ov)
            ^^^^^^^^^^^^^^^^^^^^^^^^^^^^^^
  File "C:\Users\drakkka\python\Lib\asyncio\windows_events.py", line 641, in finish_connect
    ov.getresult()
ConnectionRefusedError: [WinError 1225] The remote computer refused the network connection
[2024-10-31 07:27:44] [INFO    ] discord.gateway: Shard ID None has successfully RESUMED session 49ac14ee2d4b1eb5408d2bddfa79aae8.
[2024-10-31 08:03:53] [INFO    ] discord.gateway: Shard ID None has successfully RESUMED session 49ac14ee2d4b1eb5408d2bddfa79aae8.
[2024-10-31 08:16:16] [INFO    ] discord.gateway: Shard ID None has successfully RESUMED session 49ac14ee2d4b1eb5408d2bddfa79aae8.
[2024-10-31 08:34:09] [INFO    ] discord.gateway: Shard ID None has successfully RESUMED session 49ac14ee2d4b1eb5408d2bddfa79aae8.
Exception in thread Thread-32 (check_emote_string):
Traceback (most recent call last):
  File "C:\Users\drakkka\python\Lib\threading.py", line 1045, in _bootstrap_inner
    self.run()
  File "C:\Users\drakkka\python\Lib\threading.py", line 982, in run
    self._target(*self._args, **self._kwargs)
  File "C:\Users\drakkka\Documents\tuber stuff\aigohere\zwaif\z-waif-main\z-waif main new\utils\vtube_studio.py", line 95, in check_emote_string
    run_emote()
  File "C:\Users\drakkka\Documents\tuber stuff\aigohere\zwaif\z-waif-main\z-waif main new\utils\vtube_studio.py", line 99, in run_emote
    asyncio.run(emote())
  File "C:\Users\drakkka\python\Lib\asyncio\runners.py", line 190, in run
    return runner.run(main)
           ^^^^^^^^^^^^^^^^
  File "C:\Users\drakkka\python\Lib\asyncio\runners.py", line 118, in run
    return self._loop.run_until_complete(task)
           ^^^^^^^^^^^^^^^^^^^^^^^^^^^^^^^^^^^
  File "C:\Users\drakkka\python\Lib\asyncio\base_events.py", line 654, in run_until_complete
    return future.result()
           ^^^^^^^^^^^^^^^
  File "C:\Users\drakkka\Documents\tuber stuff\aigohere\zwaif\z-waif-main\z-waif main new\utils\vtube_studio.py", line 102, in emote
    await VTS.connect()
  File "C:\Users\drakkka\Documents\tuber stuff\aigohere\zwaif\z-waif-main\z-waif main new\venv\Lib\site-packages\pyvts\vts.py", line 82, in connect
    self.websocket = await websockets.connect(
                     ^^^^^^^^^^^^^^^^^^^^^^^^^
  File "C:\Users\drakkka\Documents\tuber stuff\aigohere\zwaif\z-waif-main\z-waif main new\venv\Lib\site-packages\websockets\legacy\client.py", line 655, in __await_impl_timeout__
    return await self.__await_impl__()
           ^^^^^^^^^^^^^^^^^^^^^^^^^^^
  File "C:\Users\drakkka\Documents\tuber stuff\aigohere\zwaif\z-waif-main\z-waif main new\venv\Lib\site-packages\websockets\legacy\client.py", line 659, in __await_impl__
    _transport, _protocol = await self._create_connection()
                            ^^^^^^^^^^^^^^^^^^^^^^^^^^^^^^^
  File "C:\Users\drakkka\python\Lib\asyncio\base_events.py", line 1091, in create_connection
    raise exceptions[0]
  File "C:\Users\drakkka\python\Lib\asyncio\base_events.py", line 1070, in create_connection
    sock = await self._connect_sock(
           ^^^^^^^^^^^^^^^^^^^^^^^^^
  File "C:\Users\drakkka\python\Lib\asyncio\base_events.py", line 974, in _connect_sock
    await self.sock_connect(sock, address)
  File "C:\Users\drakkka\python\Lib\asyncio\proactor_events.py", line 726, in sock_connect
    return await self._proactor.connect(sock, address)
           ^^^^^^^^^^^^^^^^^^^^^^^^^^^^^^^^^^^^^^^^^^^
  File "C:\Users\drakkka\python\Lib\asyncio\windows_events.py", line 854, in _poll
    value = callback(transferred, key, ov)
            ^^^^^^^^^^^^^^^^^^^^^^^^^^^^^^
  File "C:\Users\drakkka\python\Lib\asyncio\windows_events.py", line 641, in finish_connect
    ov.getresult()
ConnectionRefusedError: [WinError 1225] The remote computer refused the network connection
[2024-10-31 09:28:39] [INFO    ] discord.gateway: Shard ID None has successfully RESUMED session 49ac14ee2d4b1eb5408d2bddfa79aae8.
[2024-10-31 10:18:41] [INFO    ] discord.gateway: Shard ID None has successfully RESUMED session 49ac14ee2d4b1eb5408d2bddfa79aae8.
[2024-10-31 10:35:33] [INFO    ] discord.gateway: Shard ID None has successfully RESUMED session 49ac14ee2d4b1eb5408d2bddfa79aae8.
[2024-10-31 11:41:49] [INFO    ] discord.gateway: Shard ID None has successfully RESUMED session 49ac14ee2d4b1eb5408d2bddfa79aae8.
  Running command git clone --filter=blob:none --quiet https://github.com/openai/whisper.git 'C:\Users\drakkka\AppData\Local\Temp\pip-req-build-xl_xj8uu'

[notice] A new release of pip is available: 24.0 -> 24.3.1
[notice] To update, run: python.exe -m pip install --upgrade pip

[notice] A new release of pip is available: 24.0 -> 24.3.1
[notice] To update, run: python.exe -m pip install --upgrade pip
[2024-11-03 22:39:10] [INFO    ] discord.client: logging in using static token
[2024-11-03 22:39:12] [INFO    ] discord.gateway: Shard ID None has connected to Gateway (Session ID: f6c044669726078b1242fe61183625f0).
Exception in thread Thread-6 (run_vtube_studio_connection):
Traceback (most recent call last):
  File "C:\Users\drakkka\python\Lib\threading.py", line 1045, in _bootstrap_inner
    self.run()
  File "C:\Users\drakkka\python\Lib\threading.py", line 982, in run
    self._target(*self._args, **self._kwargs)
  File "C:\Users\drakkka\Documents\tuber stuff\aigohere\zwaif\z-waif-main\z-waif main new\utils\vtube_studio.py", line 50, in run_vtube_studio_connection
    asyncio.run(vtube_studio_connection())
  File "C:\Users\drakkka\python\Lib\asyncio\runners.py", line 190, in run
    return runner.run(main)
           ^^^^^^^^^^^^^^^^
  File "C:\Users\drakkka\python\Lib\asyncio\runners.py", line 118, in run
    return self._loop.run_until_complete(task)
           ^^^^^^^^^^^^^^^^^^^^^^^^^^^^^^^^^^^
  File "C:\Users\drakkka\python\Lib\asyncio\base_events.py", line 654, in run_until_complete
    return future.result()
           ^^^^^^^^^^^^^^^
  File "C:\Users\drakkka\Documents\tuber stuff\aigohere\zwaif\z-waif-main\z-waif main new\utils\vtube_studio.py", line 53, in vtube_studio_connection
    await VTS.connect()
  File "C:\Users\drakkka\Documents\tuber stuff\aigohere\zwaif\z-waif-main\z-waif main new\venv\Lib\site-packages\pyvts\vts.py", line 82, in connect
    self.websocket = await websockets.connect(
                     ^^^^^^^^^^^^^^^^^^^^^^^^^
  File "C:\Users\drakkka\Documents\tuber stuff\aigohere\zwaif\z-waif-main\z-waif main new\venv\Lib\site-packages\websockets\legacy\client.py", line 655, in __await_impl_timeout__
    return await self.__await_impl__()
           ^^^^^^^^^^^^^^^^^^^^^^^^^^^
  File "C:\Users\drakkka\Documents\tuber stuff\aigohere\zwaif\z-waif-main\z-waif main new\venv\Lib\site-packages\websockets\legacy\client.py", line 659, in __await_impl__
    _transport, _protocol = await self._create_connection()
                            ^^^^^^^^^^^^^^^^^^^^^^^^^^^^^^^
  File "C:\Users\drakkka\python\Lib\asyncio\base_events.py", line 1091, in create_connection
    raise exceptions[0]
  File "C:\Users\drakkka\python\Lib\asyncio\base_events.py", line 1070, in create_connection
    sock = await self._connect_sock(
           ^^^^^^^^^^^^^^^^^^^^^^^^^
  File "C:\Users\drakkka\python\Lib\asyncio\base_events.py", line 974, in _connect_sock
    await self.sock_connect(sock, address)
  File "C:\Users\drakkka\python\Lib\asyncio\proactor_events.py", line 726, in sock_connect
    return await self._proactor.connect(sock, address)
           ^^^^^^^^^^^^^^^^^^^^^^^^^^^^^^^^^^^^^^^^^^^
  File "C:\Users\drakkka\python\Lib\asyncio\windows_events.py", line 854, in _poll
    value = callback(transferred, key, ov)
            ^^^^^^^^^^^^^^^^^^^^^^^^^^^^^^
  File "C:\Users\drakkka\python\Lib\asyncio\windows_events.py", line 641, in finish_connect
    ov.getresult()
ConnectionRefusedError: [WinError 1225] The remote computer refused the network connection
[2024-11-03 22:47:07] [ERROR   ] discord.client: Ignoring exception in on_message
Traceback (most recent call last):
  File "C:\Users\drakkka\Documents\tuber stuff\aigohere\zwaif\z-waif-main\z-waif main new\venv\Lib\site-packages\discord\client.py", line 449, in _run_event
    await coro(*args, **kwargs)
  File "C:\Users\drakkka\Documents\tuber stuff\aigohere\zwaif\z-waif-main\z-waif main new\utils\z_waif_discord.py", line 57, in on_message
    await message.channel.send(message_reply)
  File "C:\Users\drakkka\Documents\tuber stuff\aigohere\zwaif\z-waif-main\z-waif main new\venv\Lib\site-packages\discord\abc.py", line 1618, in send
    data = await state.http.send_message(channel.id, params=params)
           ^^^^^^^^^^^^^^^^^^^^^^^^^^^^^^^^^^^^^^^^^^^^^^^^^^^^^^^^
  File "C:\Users\drakkka\Documents\tuber stuff\aigohere\zwaif\z-waif-main\z-waif main new\venv\Lib\site-packages\discord\http.py", line 758, in request
    raise HTTPException(response, data)
discord.errors.HTTPException: 400 Bad Request (error code: 50006): Cannot send an empty message
[2024-11-03 22:47:07] [ERROR   ] discord.client: Ignoring exception in on_message
Traceback (most recent call last):
  File "C:\Users\drakkka\Documents\tuber stuff\aigohere\zwaif\z-waif-main\z-waif main new\venv\Lib\site-packages\discord\client.py", line 449, in _run_event
    await coro(*args, **kwargs)
  File "C:\Users\drakkka\Documents\tuber stuff\aigohere\zwaif\z-waif-main\z-waif main new\utils\z_waif_discord.py", line 57, in on_message
    await message.channel.send(message_reply)
  File "C:\Users\drakkka\Documents\tuber stuff\aigohere\zwaif\z-waif-main\z-waif main new\venv\Lib\site-packages\discord\abc.py", line 1618, in send
    data = await state.http.send_message(channel.id, params=params)
           ^^^^^^^^^^^^^^^^^^^^^^^^^^^^^^^^^^^^^^^^^^^^^^^^^^^^^^^^
  File "C:\Users\drakkka\Documents\tuber stuff\aigohere\zwaif\z-waif-main\z-waif main new\venv\Lib\site-packages\discord\http.py", line 758, in request
    raise HTTPException(response, data)
discord.errors.HTTPException: 400 Bad Request (error code: 50006): Cannot send an empty message
[2024-11-03 22:47:07] [ERROR   ] discord.client: Ignoring exception in on_message
Traceback (most recent call last):
  File "C:\Users\drakkka\Documents\tuber stuff\aigohere\zwaif\z-waif-main\z-waif main new\venv\Lib\site-packages\discord\client.py", line 449, in _run_event
    await coro(*args, **kwargs)
  File "C:\Users\drakkka\Documents\tuber stuff\aigohere\zwaif\z-waif-main\z-waif main new\utils\z_waif_discord.py", line 57, in on_message
    await message.channel.send(message_reply)
  File "C:\Users\drakkka\Documents\tuber stuff\aigohere\zwaif\z-waif-main\z-waif main new\venv\Lib\site-packages\discord\abc.py", line 1618, in send
    data = await state.http.send_message(channel.id, params=params)
           ^^^^^^^^^^^^^^^^^^^^^^^^^^^^^^^^^^^^^^^^^^^^^^^^^^^^^^^^
  File "C:\Users\drakkka\Documents\tuber stuff\aigohere\zwaif\z-waif-main\z-waif main new\venv\Lib\site-packages\discord\http.py", line 758, in request
    raise HTTPException(response, data)
discord.errors.HTTPException: 400 Bad Request (error code: 50006): Cannot send an empty message
[2024-11-03 22:47:50] [ERROR   ] discord.client: Ignoring exception in on_message
Traceback (most recent call last):
  File "C:\Users\drakkka\Documents\tuber stuff\aigohere\zwaif\z-waif-main\z-waif main new\venv\Lib\site-packages\discord\client.py", line 449, in _run_event
    await coro(*args, **kwargs)
  File "C:\Users\drakkka\Documents\tuber stuff\aigohere\zwaif\z-waif-main\z-waif main new\utils\z_waif_discord.py", line 57, in on_message
    await message.channel.send(message_reply)
  File "C:\Users\drakkka\Documents\tuber stuff\aigohere\zwaif\z-waif-main\z-waif main new\venv\Lib\site-packages\discord\abc.py", line 1618, in send
    data = await state.http.send_message(channel.id, params=params)
           ^^^^^^^^^^^^^^^^^^^^^^^^^^^^^^^^^^^^^^^^^^^^^^^^^^^^^^^^
  File "C:\Users\drakkka\Documents\tuber stuff\aigohere\zwaif\z-waif-main\z-waif main new\venv\Lib\site-packages\discord\http.py", line 758, in request
    raise HTTPException(response, data)
discord.errors.HTTPException: 400 Bad Request (error code: 50006): Cannot send an empty message
[2024-11-03 22:47:50] [ERROR   ] discord.client: Ignoring exception in on_message
Traceback (most recent call last):
  File "C:\Users\drakkka\Documents\tuber stuff\aigohere\zwaif\z-waif-main\z-waif main new\venv\Lib\site-packages\discord\client.py", line 449, in _run_event
    await coro(*args, **kwargs)
  File "C:\Users\drakkka\Documents\tuber stuff\aigohere\zwaif\z-waif-main\z-waif main new\utils\z_waif_discord.py", line 57, in on_message
    await message.channel.send(message_reply)
  File "C:\Users\drakkka\Documents\tuber stuff\aigohere\zwaif\z-waif-main\z-waif main new\venv\Lib\site-packages\discord\abc.py", line 1618, in send
    data = await state.http.send_message(channel.id, params=params)
           ^^^^^^^^^^^^^^^^^^^^^^^^^^^^^^^^^^^^^^^^^^^^^^^^^^^^^^^^
  File "C:\Users\drakkka\Documents\tuber stuff\aigohere\zwaif\z-waif-main\z-waif main new\venv\Lib\site-packages\discord\http.py", line 758, in request
    raise HTTPException(response, data)
discord.errors.HTTPException: 400 Bad Request (error code: 50006): Cannot send an empty message
[2024-11-03 22:47:51] [ERROR   ] discord.client: Ignoring exception in on_message
Traceback (most recent call last):
  File "C:\Users\drakkka\Documents\tuber stuff\aigohere\zwaif\z-waif-main\z-waif main new\venv\Lib\site-packages\discord\client.py", line 449, in _run_event
    await coro(*args, **kwargs)
  File "C:\Users\drakkka\Documents\tuber stuff\aigohere\zwaif\z-waif-main\z-waif main new\utils\z_waif_discord.py", line 57, in on_message
    await message.channel.send(message_reply)
  File "C:\Users\drakkka\Documents\tuber stuff\aigohere\zwaif\z-waif-main\z-waif main new\venv\Lib\site-packages\discord\abc.py", line 1618, in send
    data = await state.http.send_message(channel.id, params=params)
           ^^^^^^^^^^^^^^^^^^^^^^^^^^^^^^^^^^^^^^^^^^^^^^^^^^^^^^^^
  File "C:\Users\drakkka\Documents\tuber stuff\aigohere\zwaif\z-waif-main\z-waif main new\venv\Lib\site-packages\discord\http.py", line 758, in request
    raise HTTPException(response, data)
discord.errors.HTTPException: 400 Bad Request (error code: 50006): Cannot send an empty message
[2024-11-03 22:48:12] [ERROR   ] discord.client: Ignoring exception in on_message
Traceback (most recent call last):
  File "C:\Users\drakkka\Documents\tuber stuff\aigohere\zwaif\z-waif-main\z-waif main new\venv\Lib\site-packages\discord\client.py", line 449, in _run_event
    await coro(*args, **kwargs)
  File "C:\Users\drakkka\Documents\tuber stuff\aigohere\zwaif\z-waif-main\z-waif main new\utils\z_waif_discord.py", line 57, in on_message
    await message.channel.send(message_reply)
  File "C:\Users\drakkka\Documents\tuber stuff\aigohere\zwaif\z-waif-main\z-waif main new\venv\Lib\site-packages\discord\abc.py", line 1618, in send
    data = await state.http.send_message(channel.id, params=params)
           ^^^^^^^^^^^^^^^^^^^^^^^^^^^^^^^^^^^^^^^^^^^^^^^^^^^^^^^^
  File "C:\Users\drakkka\Documents\tuber stuff\aigohere\zwaif\z-waif-main\z-waif main new\venv\Lib\site-packages\discord\http.py", line 758, in request
    raise HTTPException(response, data)
discord.errors.HTTPException: 400 Bad Request (error code: 50006): Cannot send an empty message
[2024-11-03 22:48:20] [ERROR   ] discord.client: Ignoring exception in on_message
Traceback (most recent call last):
  File "C:\Users\drakkka\Documents\tuber stuff\aigohere\zwaif\z-waif-main\z-waif main new\venv\Lib\site-packages\discord\client.py", line 449, in _run_event
    await coro(*args, **kwargs)
  File "C:\Users\drakkka\Documents\tuber stuff\aigohere\zwaif\z-waif-main\z-waif main new\utils\z_waif_discord.py", line 57, in on_message
    await message.channel.send(message_reply)
  File "C:\Users\drakkka\Documents\tuber stuff\aigohere\zwaif\z-waif-main\z-waif main new\venv\Lib\site-packages\discord\abc.py", line 1618, in send
    data = await state.http.send_message(channel.id, params=params)
           ^^^^^^^^^^^^^^^^^^^^^^^^^^^^^^^^^^^^^^^^^^^^^^^^^^^^^^^^
  File "C:\Users\drakkka\Documents\tuber stuff\aigohere\zwaif\z-waif-main\z-waif main new\venv\Lib\site-packages\discord\http.py", line 758, in request
    raise HTTPException(response, data)
discord.errors.HTTPException: 400 Bad Request (error code: 50006): Cannot send an empty message
[2024-11-03 22:49:36] [ERROR   ] discord.client: Ignoring exception in on_message
Traceback (most recent call last):
  File "C:\Users\drakkka\Documents\tuber stuff\aigohere\zwaif\z-waif-main\z-waif main new\venv\Lib\site-packages\discord\client.py", line 449, in _run_event
    await coro(*args, **kwargs)
  File "C:\Users\drakkka\Documents\tuber stuff\aigohere\zwaif\z-waif-main\z-waif main new\utils\z_waif_discord.py", line 57, in on_message
    await message.channel.send(message_reply)
  File "C:\Users\drakkka\Documents\tuber stuff\aigohere\zwaif\z-waif-main\z-waif main new\venv\Lib\site-packages\discord\abc.py", line 1618, in send
    data = await state.http.send_message(channel.id, params=params)
           ^^^^^^^^^^^^^^^^^^^^^^^^^^^^^^^^^^^^^^^^^^^^^^^^^^^^^^^^
  File "C:\Users\drakkka\Documents\tuber stuff\aigohere\zwaif\z-waif-main\z-waif main new\venv\Lib\site-packages\discord\http.py", line 758, in request
    raise HTTPException(response, data)
discord.errors.HTTPException: 400 Bad Request (error code: 50006): Cannot send an empty message
[2024-11-03 22:49:36] [ERROR   ] discord.client: Ignoring exception in on_message
Traceback (most recent call last):
  File "C:\Users\drakkka\Documents\tuber stuff\aigohere\zwaif\z-waif-main\z-waif main new\venv\Lib\site-packages\discord\client.py", line 449, in _run_event
    await coro(*args, **kwargs)
  File "C:\Users\drakkka\Documents\tuber stuff\aigohere\zwaif\z-waif-main\z-waif main new\utils\z_waif_discord.py", line 57, in on_message
    await message.channel.send(message_reply)
  File "C:\Users\drakkka\Documents\tuber stuff\aigohere\zwaif\z-waif-main\z-waif main new\venv\Lib\site-packages\discord\abc.py", line 1618, in send
    data = await state.http.send_message(channel.id, params=params)
           ^^^^^^^^^^^^^^^^^^^^^^^^^^^^^^^^^^^^^^^^^^^^^^^^^^^^^^^^
  File "C:\Users\drakkka\Documents\tuber stuff\aigohere\zwaif\z-waif-main\z-waif main new\venv\Lib\site-packages\discord\http.py", line 758, in request
    raise HTTPException(response, data)
discord.errors.HTTPException: 400 Bad Request (error code: 50006): Cannot send an empty message
[2024-11-03 22:49:36] [ERROR   ] discord.client: Ignoring exception in on_message
Traceback (most recent call last):
  File "C:\Users\drakkka\Documents\tuber stuff\aigohere\zwaif\z-waif-main\z-waif main new\venv\Lib\site-packages\discord\client.py", line 449, in _run_event
    await coro(*args, **kwargs)
  File "C:\Users\drakkka\Documents\tuber stuff\aigohere\zwaif\z-waif-main\z-waif main new\utils\z_waif_discord.py", line 57, in on_message
    await message.channel.send(message_reply)
  File "C:\Users\drakkka\Documents\tuber stuff\aigohere\zwaif\z-waif-main\z-waif main new\venv\Lib\site-packages\discord\abc.py", line 1618, in send
    data = await state.http.send_message(channel.id, params=params)
           ^^^^^^^^^^^^^^^^^^^^^^^^^^^^^^^^^^^^^^^^^^^^^^^^^^^^^^^^
  File "C:\Users\drakkka\Documents\tuber stuff\aigohere\zwaif\z-waif-main\z-waif main new\venv\Lib\site-packages\discord\http.py", line 758, in request
    raise HTTPException(response, data)
discord.errors.HTTPException: 400 Bad Request (error code: 50006): Cannot send an empty message
[2024-11-03 22:50:51] [ERROR   ] discord.client: Ignoring exception in on_message
Traceback (most recent call last):
  File "C:\Users\drakkka\Documents\tuber stuff\aigohere\zwaif\z-waif-main\z-waif main new\venv\Lib\site-packages\discord\client.py", line 449, in _run_event
    await coro(*args, **kwargs)
  File "C:\Users\drakkka\Documents\tuber stuff\aigohere\zwaif\z-waif-main\z-waif main new\utils\z_waif_discord.py", line 57, in on_message
    await message.channel.send(message_reply)
  File "C:\Users\drakkka\Documents\tuber stuff\aigohere\zwaif\z-waif-main\z-waif main new\venv\Lib\site-packages\discord\abc.py", line 1618, in send
    data = await state.http.send_message(channel.id, params=params)
           ^^^^^^^^^^^^^^^^^^^^^^^^^^^^^^^^^^^^^^^^^^^^^^^^^^^^^^^^
  File "C:\Users\drakkka\Documents\tuber stuff\aigohere\zwaif\z-waif-main\z-waif main new\venv\Lib\site-packages\discord\http.py", line 758, in request
    raise HTTPException(response, data)
discord.errors.HTTPException: 400 Bad Request (error code: 50006): Cannot send an empty message
[2024-11-03 22:50:52] [ERROR   ] discord.client: Ignoring exception in on_message
Traceback (most recent call last):
  File "C:\Users\drakkka\Documents\tuber stuff\aigohere\zwaif\z-waif-main\z-waif main new\venv\Lib\site-packages\discord\client.py", line 449, in _run_event
    await coro(*args, **kwargs)
  File "C:\Users\drakkka\Documents\tuber stuff\aigohere\zwaif\z-waif-main\z-waif main new\utils\z_waif_discord.py", line 57, in on_message
    await message.channel.send(message_reply)
  File "C:\Users\drakkka\Documents\tuber stuff\aigohere\zwaif\z-waif-main\z-waif main new\venv\Lib\site-packages\discord\abc.py", line 1618, in send
    data = await state.http.send_message(channel.id, params=params)
           ^^^^^^^^^^^^^^^^^^^^^^^^^^^^^^^^^^^^^^^^^^^^^^^^^^^^^^^^
  File "C:\Users\drakkka\Documents\tuber stuff\aigohere\zwaif\z-waif-main\z-waif main new\venv\Lib\site-packages\discord\http.py", line 758, in request
    raise HTTPException(response, data)
discord.errors.HTTPException: 400 Bad Request (error code: 50006): Cannot send an empty message
[2024-11-03 22:50:54] [ERROR   ] discord.client: Ignoring exception in on_message
Traceback (most recent call last):
  File "C:\Users\drakkka\Documents\tuber stuff\aigohere\zwaif\z-waif-main\z-waif main new\venv\Lib\site-packages\discord\client.py", line 449, in _run_event
    await coro(*args, **kwargs)
  File "C:\Users\drakkka\Documents\tuber stuff\aigohere\zwaif\z-waif-main\z-waif main new\utils\z_waif_discord.py", line 57, in on_message
    await message.channel.send(message_reply)
  File "C:\Users\drakkka\Documents\tuber stuff\aigohere\zwaif\z-waif-main\z-waif main new\venv\Lib\site-packages\discord\abc.py", line 1618, in send
    data = await state.http.send_message(channel.id, params=params)
           ^^^^^^^^^^^^^^^^^^^^^^^^^^^^^^^^^^^^^^^^^^^^^^^^^^^^^^^^
  File "C:\Users\drakkka\Documents\tuber stuff\aigohere\zwaif\z-waif-main\z-waif main new\venv\Lib\site-packages\discord\http.py", line 758, in request
    raise HTTPException(response, data)
discord.errors.HTTPException: 400 Bad Request (error code: 50006): Cannot send an empty message
Exception in thread Thread-29 (check_emote_string):
Traceback (most recent call last):
  File "C:\Users\drakkka\python\Lib\threading.py", line 1045, in _bootstrap_inner
    self.run()
  File "C:\Users\drakkka\python\Lib\threading.py", line 982, in run
    self._target(*self._args, **self._kwargs)
  File "C:\Users\drakkka\Documents\tuber stuff\aigohere\zwaif\z-waif-main\z-waif main new\utils\vtube_studio.py", line 95, in check_emote_string
    run_emote()
  File "C:\Users\drakkka\Documents\tuber stuff\aigohere\zwaif\z-waif-main\z-waif main new\utils\vtube_studio.py", line 99, in run_emote
    asyncio.run(emote())
  File "C:\Users\drakkka\python\Lib\asyncio\runners.py", line 190, in run
    return runner.run(main)
           ^^^^^^^^^^^^^^^^
  File "C:\Users\drakkka\python\Lib\asyncio\runners.py", line 118, in run
    return self._loop.run_until_complete(task)
           ^^^^^^^^^^^^^^^^^^^^^^^^^^^^^^^^^^^
  File "C:\Users\drakkka\python\Lib\asyncio\base_events.py", line 654, in run_until_complete
    return future.result()
           ^^^^^^^^^^^^^^^
  File "C:\Users\drakkka\Documents\tuber stuff\aigohere\zwaif\z-waif-main\z-waif main new\utils\vtube_studio.py", line 102, in emote
    await VTS.connect()
  File "C:\Users\drakkka\Documents\tuber stuff\aigohere\zwaif\z-waif-main\z-waif main new\venv\Lib\site-packages\pyvts\vts.py", line 82, in connect
    self.websocket = await websockets.connect(
                     ^^^^^^^^^^^^^^^^^^^^^^^^^
  File "C:\Users\drakkka\Documents\tuber stuff\aigohere\zwaif\z-waif-main\z-waif main new\venv\Lib\site-packages\websockets\legacy\client.py", line 655, in __await_impl_timeout__
    return await self.__await_impl__()
           ^^^^^^^^^^^^^^^^^^^^^^^^^^^
  File "C:\Users\drakkka\Documents\tuber stuff\aigohere\zwaif\z-waif-main\z-waif main new\venv\Lib\site-packages\websockets\legacy\client.py", line 659, in __await_impl__
    _transport, _protocol = await self._create_connection()
                            ^^^^^^^^^^^^^^^^^^^^^^^^^^^^^^^
  File "C:\Users\drakkka\python\Lib\asyncio\base_events.py", line 1091, in create_connection
    raise exceptions[0]
  File "C:\Users\drakkka\python\Lib\asyncio\base_events.py", line 1070, in create_connection
    sock = await self._connect_sock(
           ^^^^^^^^^^^^^^^^^^^^^^^^^
  File "C:\Users\drakkka\python\Lib\asyncio\base_events.py", line 974, in _connect_sock
    await self.sock_connect(sock, address)
  File "C:\Users\drakkka\python\Lib\asyncio\proactor_events.py", line 726, in sock_connect
    return await self._proactor.connect(sock, address)
           ^^^^^^^^^^^^^^^^^^^^^^^^^^^^^^^^^^^^^^^^^^^
  File "C:\Users\drakkka\python\Lib\asyncio\windows_events.py", line 854, in _poll
    value = callback(transferred, key, ov)
            ^^^^^^^^^^^^^^^^^^^^^^^^^^^^^^
  File "C:\Users\drakkka\python\Lib\asyncio\windows_events.py", line 641, in finish_connect
    ov.getresult()
ConnectionRefusedError: [WinError 1225] The remote computer refused the network connection
Exception in thread Thread-32 (check_emote_string):
Traceback (most recent call last):
  File "C:\Users\drakkka\python\Lib\threading.py", line 1045, in _bootstrap_inner
    self.run()
  File "C:\Users\drakkka\python\Lib\threading.py", line 982, in run
    self._target(*self._args, **self._kwargs)
  File "C:\Users\drakkka\Documents\tuber stuff\aigohere\zwaif\z-waif-main\z-waif main new\utils\vtube_studio.py", line 95, in check_emote_string
    run_emote()
  File "C:\Users\drakkka\Documents\tuber stuff\aigohere\zwaif\z-waif-main\z-waif main new\utils\vtube_studio.py", line 99, in run_emote
    asyncio.run(emote())
  File "C:\Users\drakkka\python\Lib\asyncio\runners.py", line 190, in run
    return runner.run(main)
           ^^^^^^^^^^^^^^^^
  File "C:\Users\drakkka\python\Lib\asyncio\runners.py", line 118, in run
    return self._loop.run_until_complete(task)
           ^^^^^^^^^^^^^^^^^^^^^^^^^^^^^^^^^^^
  File "C:\Users\drakkka\python\Lib\asyncio\base_events.py", line 654, in run_until_complete
    return future.result()
           ^^^^^^^^^^^^^^^
  File "C:\Users\drakkka\Documents\tuber stuff\aigohere\zwaif\z-waif-main\z-waif main new\utils\vtube_studio.py", line 102, in emote
    await VTS.connect()
  File "C:\Users\drakkka\Documents\tuber stuff\aigohere\zwaif\z-waif-main\z-waif main new\venv\Lib\site-packages\pyvts\vts.py", line 82, in connect
    self.websocket = await websockets.connect(
                     ^^^^^^^^^^^^^^^^^^^^^^^^^
  File "C:\Users\drakkka\Documents\tuber stuff\aigohere\zwaif\z-waif-main\z-waif main new\venv\Lib\site-packages\websockets\legacy\client.py", line 655, in __await_impl_timeout__
    return await self.__await_impl__()
           ^^^^^^^^^^^^^^^^^^^^^^^^^^^
  File "C:\Users\drakkka\Documents\tuber stuff\aigohere\zwaif\z-waif-main\z-waif main new\venv\Lib\site-packages\websockets\legacy\client.py", line 659, in __await_impl__
    _transport, _protocol = await self._create_connection()
                            ^^^^^^^^^^^^^^^^^^^^^^^^^^^^^^^
  File "C:\Users\drakkka\python\Lib\asyncio\base_events.py", line 1091, in create_connection
    raise exceptions[0]
  File "C:\Users\drakkka\python\Lib\asyncio\base_events.py", line 1070, in create_connection
    sock = await self._connect_sock(
           ^^^^^^^^^^^^^^^^^^^^^^^^^
  File "C:\Users\drakkka\python\Lib\asyncio\base_events.py", line 974, in _connect_sock
    await self.sock_connect(sock, address)
  File "C:\Users\drakkka\python\Lib\asyncio\proactor_events.py", line 726, in sock_connect
    return await self._proactor.connect(sock, address)
           ^^^^^^^^^^^^^^^^^^^^^^^^^^^^^^^^^^^^^^^^^^^
  File "C:\Users\drakkka\python\Lib\asyncio\windows_events.py", line 854, in _poll
    value = callback(transferred, key, ov)
            ^^^^^^^^^^^^^^^^^^^^^^^^^^^^^^
  File "C:\Users\drakkka\python\Lib\asyncio\windows_events.py", line 641, in finish_connect
    ov.getresult()
ConnectionRefusedError: [WinError 1225] The remote computer refused the network connection
Exception in thread Thread-38 (check_emote_string):
Traceback (most recent call last):
  File "C:\Users\drakkka\python\Lib\threading.py", line 1045, in _bootstrap_inner
    self.run()
  File "C:\Users\drakkka\python\Lib\threading.py", line 982, in run
    self._target(*self._args, **self._kwargs)
  File "C:\Users\drakkka\Documents\tuber stuff\aigohere\zwaif\z-waif-main\z-waif main new\utils\vtube_studio.py", line 95, in check_emote_string
    run_emote()
  File "C:\Users\drakkka\Documents\tuber stuff\aigohere\zwaif\z-waif-main\z-waif main new\utils\vtube_studio.py", line 99, in run_emote
    asyncio.run(emote())
  File "C:\Users\drakkka\python\Lib\asyncio\runners.py", line 190, in run
    return runner.run(main)
           ^^^^^^^^^^^^^^^^
  File "C:\Users\drakkka\python\Lib\asyncio\runners.py", line 118, in run
    return self._loop.run_until_complete(task)
           ^^^^^^^^^^^^^^^^^^^^^^^^^^^^^^^^^^^
  File "C:\Users\drakkka\python\Lib\asyncio\base_events.py", line 654, in run_until_complete
    return future.result()
           ^^^^^^^^^^^^^^^
  File "C:\Users\drakkka\Documents\tuber stuff\aigohere\zwaif\z-waif-main\z-waif main new\utils\vtube_studio.py", line 102, in emote
    await VTS.connect()
  File "C:\Users\drakkka\Documents\tuber stuff\aigohere\zwaif\z-waif-main\z-waif main new\venv\Lib\site-packages\pyvts\vts.py", line 82, in connect
    self.websocket = await websockets.connect(
                     ^^^^^^^^^^^^^^^^^^^^^^^^^
  File "C:\Users\drakkka\Documents\tuber stuff\aigohere\zwaif\z-waif-main\z-waif main new\venv\Lib\site-packages\websockets\legacy\client.py", line 655, in __await_impl_timeout__
    return await self.__await_impl__()
           ^^^^^^^^^^^^^^^^^^^^^^^^^^^
  File "C:\Users\drakkka\Documents\tuber stuff\aigohere\zwaif\z-waif-main\z-waif main new\venv\Lib\site-packages\websockets\legacy\client.py", line 659, in __await_impl__
    _transport, _protocol = await self._create_connection()
                            ^^^^^^^^^^^^^^^^^^^^^^^^^^^^^^^
  File "C:\Users\drakkka\python\Lib\asyncio\base_events.py", line 1091, in create_connection
    raise exceptions[0]
  File "C:\Users\drakkka\python\Lib\asyncio\base_events.py", line 1070, in create_connection
    sock = await self._connect_sock(
           ^^^^^^^^^^^^^^^^^^^^^^^^^
  File "C:\Users\drakkka\python\Lib\asyncio\base_events.py", line 974, in _connect_sock
    await self.sock_connect(sock, address)
  File "C:\Users\drakkka\python\Lib\asyncio\proactor_events.py", line 726, in sock_connect
    return await self._proactor.connect(sock, address)
           ^^^^^^^^^^^^^^^^^^^^^^^^^^^^^^^^^^^^^^^^^^^
  File "C:\Users\drakkka\python\Lib\asyncio\windows_events.py", line 854, in _poll
    value = callback(transferred, key, ov)
            ^^^^^^^^^^^^^^^^^^^^^^^^^^^^^^
  File "C:\Users\drakkka\python\Lib\asyncio\windows_events.py", line 641, in finish_connect
    ov.getresult()
ConnectionRefusedError: [WinError 1225] The remote computer refused the network connection
Exception in thread Thread-40 (check_emote_string):
Traceback (most recent call last):
  File "C:\Users\drakkka\python\Lib\threading.py", line 1045, in _bootstrap_inner
    self.run()
  File "C:\Users\drakkka\python\Lib\threading.py", line 982, in run
    self._target(*self._args, **self._kwargs)
  File "C:\Users\drakkka\Documents\tuber stuff\aigohere\zwaif\z-waif-main\z-waif main new\utils\vtube_studio.py", line 95, in check_emote_string
    run_emote()
  File "C:\Users\drakkka\Documents\tuber stuff\aigohere\zwaif\z-waif-main\z-waif main new\utils\vtube_studio.py", line 99, in run_emote
    asyncio.run(emote())
  File "C:\Users\drakkka\python\Lib\asyncio\runners.py", line 190, in run
    return runner.run(main)
           ^^^^^^^^^^^^^^^^
  File "C:\Users\drakkka\python\Lib\asyncio\runners.py", line 118, in run
    return self._loop.run_until_complete(task)
           ^^^^^^^^^^^^^^^^^^^^^^^^^^^^^^^^^^^
  File "C:\Users\drakkka\python\Lib\asyncio\base_events.py", line 654, in run_until_complete
    return future.result()
           ^^^^^^^^^^^^^^^
  File "C:\Users\drakkka\Documents\tuber stuff\aigohere\zwaif\z-waif-main\z-waif main new\utils\vtube_studio.py", line 102, in emote
    await VTS.connect()
  File "C:\Users\drakkka\Documents\tuber stuff\aigohere\zwaif\z-waif-main\z-waif main new\venv\Lib\site-packages\pyvts\vts.py", line 82, in connect
    self.websocket = await websockets.connect(
                     ^^^^^^^^^^^^^^^^^^^^^^^^^
  File "C:\Users\drakkka\Documents\tuber stuff\aigohere\zwaif\z-waif-main\z-waif main new\venv\Lib\site-packages\websockets\legacy\client.py", line 655, in __await_impl_timeout__
    return await self.__await_impl__()
           ^^^^^^^^^^^^^^^^^^^^^^^^^^^
  File "C:\Users\drakkka\Documents\tuber stuff\aigohere\zwaif\z-waif-main\z-waif main new\venv\Lib\site-packages\websockets\legacy\client.py", line 659, in __await_impl__
    _transport, _protocol = await self._create_connection()
                            ^^^^^^^^^^^^^^^^^^^^^^^^^^^^^^^
  File "C:\Users\drakkka\python\Lib\asyncio\base_events.py", line 1091, in create_connection
    raise exceptions[0]
  File "C:\Users\drakkka\python\Lib\asyncio\base_events.py", line 1070, in create_connection
    sock = await self._connect_sock(
           ^^^^^^^^^^^^^^^^^^^^^^^^^
  File "C:\Users\drakkka\python\Lib\asyncio\base_events.py", line 974, in _connect_sock
    await self.sock_connect(sock, address)
  File "C:\Users\drakkka\python\Lib\asyncio\proactor_events.py", line 726, in sock_connect
    return await self._proactor.connect(sock, address)
           ^^^^^^^^^^^^^^^^^^^^^^^^^^^^^^^^^^^^^^^^^^^
  File "C:\Users\drakkka\python\Lib\asyncio\windows_events.py", line 854, in _poll
    value = callback(transferred, key, ov)
            ^^^^^^^^^^^^^^^^^^^^^^^^^^^^^^
  File "C:\Users\drakkka\python\Lib\asyncio\windows_events.py", line 641, in finish_connect
    ov.getresult()
ConnectionRefusedError: [WinError 1225] The remote computer refused the network connection
[2024-11-04 01:26:27] [INFO    ] discord.gateway: Shard ID None has successfully RESUMED session f6c044669726078b1242fe61183625f0.
[2024-11-04 04:31:22] [INFO    ] discord.gateway: Shard ID None has successfully RESUMED session f6c044669726078b1242fe61183625f0.
Exception in thread Thread-43 (check_emote_string):
Traceback (most recent call last):
  File "C:\Users\drakkka\python\Lib\threading.py", line 1045, in _bootstrap_inner
    self.run()
  File "C:\Users\drakkka\python\Lib\threading.py", line 982, in run
    self._target(*self._args, **self._kwargs)
  File "C:\Users\drakkka\Documents\tuber stuff\aigohere\zwaif\z-waif-main\z-waif main new\utils\vtube_studio.py", line 95, in check_emote_string
    run_emote()
  File "C:\Users\drakkka\Documents\tuber stuff\aigohere\zwaif\z-waif-main\z-waif main new\utils\vtube_studio.py", line 99, in run_emote
    asyncio.run(emote())
  File "C:\Users\drakkka\python\Lib\asyncio\runners.py", line 190, in run
    return runner.run(main)
           ^^^^^^^^^^^^^^^^
  File "C:\Users\drakkka\python\Lib\asyncio\runners.py", line 118, in run
    return self._loop.run_until_complete(task)
           ^^^^^^^^^^^^^^^^^^^^^^^^^^^^^^^^^^^
  File "C:\Users\drakkka\python\Lib\asyncio\base_events.py", line 654, in run_until_complete
    return future.result()
           ^^^^^^^^^^^^^^^
  File "C:\Users\drakkka\Documents\tuber stuff\aigohere\zwaif\z-waif-main\z-waif main new\utils\vtube_studio.py", line 102, in emote
    await VTS.connect()
  File "C:\Users\drakkka\Documents\tuber stuff\aigohere\zwaif\z-waif-main\z-waif main new\venv\Lib\site-packages\pyvts\vts.py", line 82, in connect
    self.websocket = await websockets.connect(
                     ^^^^^^^^^^^^^^^^^^^^^^^^^
  File "C:\Users\drakkka\Documents\tuber stuff\aigohere\zwaif\z-waif-main\z-waif main new\venv\Lib\site-packages\websockets\legacy\client.py", line 655, in __await_impl_timeout__
    return await self.__await_impl__()
           ^^^^^^^^^^^^^^^^^^^^^^^^^^^
  File "C:\Users\drakkka\Documents\tuber stuff\aigohere\zwaif\z-waif-main\z-waif main new\venv\Lib\site-packages\websockets\legacy\client.py", line 659, in __await_impl__
    _transport, _protocol = await self._create_connection()
                            ^^^^^^^^^^^^^^^^^^^^^^^^^^^^^^^
  File "C:\Users\drakkka\python\Lib\asyncio\base_events.py", line 1091, in create_connection
    raise exceptions[0]
  File "C:\Users\drakkka\python\Lib\asyncio\base_events.py", line 1070, in create_connection
    sock = await self._connect_sock(
           ^^^^^^^^^^^^^^^^^^^^^^^^^
  File "C:\Users\drakkka\python\Lib\asyncio\base_events.py", line 974, in _connect_sock
    await self.sock_connect(sock, address)
  File "C:\Users\drakkka\python\Lib\asyncio\proactor_events.py", line 726, in sock_connect
    return await self._proactor.connect(sock, address)
           ^^^^^^^^^^^^^^^^^^^^^^^^^^^^^^^^^^^^^^^^^^^
  File "C:\Users\drakkka\python\Lib\asyncio\windows_events.py", line 854, in _poll
    value = callback(transferred, key, ov)
            ^^^^^^^^^^^^^^^^^^^^^^^^^^^^^^
  File "C:\Users\drakkka\python\Lib\asyncio\windows_events.py", line 641, in finish_connect
    ov.getresult()
ConnectionRefusedError: [WinError 1225] The remote computer refused the network connection
Exception in thread Thread-46 (check_emote_string):
Traceback (most recent call last):
  File "C:\Users\drakkka\python\Lib\threading.py", line 1045, in _bootstrap_inner
    self.run()
  File "C:\Users\drakkka\python\Lib\threading.py", line 982, in run
    self._target(*self._args, **self._kwargs)
  File "C:\Users\drakkka\Documents\tuber stuff\aigohere\zwaif\z-waif-main\z-waif main new\utils\vtube_studio.py", line 95, in check_emote_string
    run_emote()
  File "C:\Users\drakkka\Documents\tuber stuff\aigohere\zwaif\z-waif-main\z-waif main new\utils\vtube_studio.py", line 99, in run_emote
    asyncio.run(emote())
  File "C:\Users\drakkka\python\Lib\asyncio\runners.py", line 190, in run
    return runner.run(main)
           ^^^^^^^^^^^^^^^^
  File "C:\Users\drakkka\python\Lib\asyncio\runners.py", line 118, in run
    return self._loop.run_until_complete(task)
           ^^^^^^^^^^^^^^^^^^^^^^^^^^^^^^^^^^^
  File "C:\Users\drakkka\python\Lib\asyncio\base_events.py", line 654, in run_until_complete
    return future.result()
           ^^^^^^^^^^^^^^^
  File "C:\Users\drakkka\Documents\tuber stuff\aigohere\zwaif\z-waif-main\z-waif main new\utils\vtube_studio.py", line 102, in emote
    await VTS.connect()
  File "C:\Users\drakkka\Documents\tuber stuff\aigohere\zwaif\z-waif-main\z-waif main new\venv\Lib\site-packages\pyvts\vts.py", line 82, in connect
    self.websocket = await websockets.connect(
                     ^^^^^^^^^^^^^^^^^^^^^^^^^
  File "C:\Users\drakkka\Documents\tuber stuff\aigohere\zwaif\z-waif-main\z-waif main new\venv\Lib\site-packages\websockets\legacy\client.py", line 655, in __await_impl_timeout__
    return await self.__await_impl__()
           ^^^^^^^^^^^^^^^^^^^^^^^^^^^
  File "C:\Users\drakkka\Documents\tuber stuff\aigohere\zwaif\z-waif-main\z-waif main new\venv\Lib\site-packages\websockets\legacy\client.py", line 659, in __await_impl__
    _transport, _protocol = await self._create_connection()
                            ^^^^^^^^^^^^^^^^^^^^^^^^^^^^^^^
  File "C:\Users\drakkka\python\Lib\asyncio\base_events.py", line 1091, in create_connection
    raise exceptions[0]
  File "C:\Users\drakkka\python\Lib\asyncio\base_events.py", line 1070, in create_connection
    sock = await self._connect_sock(
           ^^^^^^^^^^^^^^^^^^^^^^^^^
  File "C:\Users\drakkka\python\Lib\asyncio\base_events.py", line 974, in _connect_sock
    await self.sock_connect(sock, address)
  File "C:\Users\drakkka\python\Lib\asyncio\proactor_events.py", line 726, in sock_connect
    return await self._proactor.connect(sock, address)
           ^^^^^^^^^^^^^^^^^^^^^^^^^^^^^^^^^^^^^^^^^^^
  File "C:\Users\drakkka\python\Lib\asyncio\windows_events.py", line 854, in _poll
    value = callback(transferred, key, ov)
            ^^^^^^^^^^^^^^^^^^^^^^^^^^^^^^
  File "C:\Users\drakkka\python\Lib\asyncio\windows_events.py", line 641, in finish_connect
    ov.getresult()
ConnectionRefusedError: [WinError 1225] The remote computer refused the network connection
Exception in thread Thread-49 (check_emote_string):
Traceback (most recent call last):
  File "C:\Users\drakkka\python\Lib\threading.py", line 1045, in _bootstrap_inner
    self.run()
  File "C:\Users\drakkka\python\Lib\threading.py", line 982, in run
    self._target(*self._args, **self._kwargs)
  File "C:\Users\drakkka\Documents\tuber stuff\aigohere\zwaif\z-waif-main\z-waif main new\utils\vtube_studio.py", line 95, in check_emote_string
    run_emote()
  File "C:\Users\drakkka\Documents\tuber stuff\aigohere\zwaif\z-waif-main\z-waif main new\utils\vtube_studio.py", line 99, in run_emote
    asyncio.run(emote())
  File "C:\Users\drakkka\python\Lib\asyncio\runners.py", line 190, in run
    return runner.run(main)
           ^^^^^^^^^^^^^^^^
  File "C:\Users\drakkka\python\Lib\asyncio\runners.py", line 118, in run
    return self._loop.run_until_complete(task)
           ^^^^^^^^^^^^^^^^^^^^^^^^^^^^^^^^^^^
  File "C:\Users\drakkka\python\Lib\asyncio\base_events.py", line 654, in run_until_complete
    return future.result()
           ^^^^^^^^^^^^^^^
  File "C:\Users\drakkka\Documents\tuber stuff\aigohere\zwaif\z-waif-main\z-waif main new\utils\vtube_studio.py", line 102, in emote
    await VTS.connect()
  File "C:\Users\drakkka\Documents\tuber stuff\aigohere\zwaif\z-waif-main\z-waif main new\venv\Lib\site-packages\pyvts\vts.py", line 82, in connect
    self.websocket = await websockets.connect(
                     ^^^^^^^^^^^^^^^^^^^^^^^^^
  File "C:\Users\drakkka\Documents\tuber stuff\aigohere\zwaif\z-waif-main\z-waif main new\venv\Lib\site-packages\websockets\legacy\client.py", line 655, in __await_impl_timeout__
    return await self.__await_impl__()
           ^^^^^^^^^^^^^^^^^^^^^^^^^^^
  File "C:\Users\drakkka\Documents\tuber stuff\aigohere\zwaif\z-waif-main\z-waif main new\venv\Lib\site-packages\websockets\legacy\client.py", line 659, in __await_impl__
    _transport, _protocol = await self._create_connection()
                            ^^^^^^^^^^^^^^^^^^^^^^^^^^^^^^^
  File "C:\Users\drakkka\python\Lib\asyncio\base_events.py", line 1091, in create_connection
    raise exceptions[0]
  File "C:\Users\drakkka\python\Lib\asyncio\base_events.py", line 1070, in create_connection
    sock = await self._connect_sock(
           ^^^^^^^^^^^^^^^^^^^^^^^^^
  File "C:\Users\drakkka\python\Lib\asyncio\base_events.py", line 974, in _connect_sock
    await self.sock_connect(sock, address)
  File "C:\Users\drakkka\python\Lib\asyncio\proactor_events.py", line 726, in sock_connect
    return await self._proactor.connect(sock, address)
           ^^^^^^^^^^^^^^^^^^^^^^^^^^^^^^^^^^^^^^^^^^^
  File "C:\Users\drakkka\python\Lib\asyncio\windows_events.py", line 854, in _poll
    value = callback(transferred, key, ov)
            ^^^^^^^^^^^^^^^^^^^^^^^^^^^^^^
  File "C:\Users\drakkka\python\Lib\asyncio\windows_events.py", line 641, in finish_connect
    ov.getresult()
ConnectionRefusedError: [WinError 1225] The remote computer refused the network connection
[2024-11-04 08:03:26] [INFO    ] discord.gateway: Shard ID None has successfully RESUMED session f6c044669726078b1242fe61183625f0.
Exception in thread Thread-51 (check_emote_string):
Traceback (most recent call last):
  File "C:\Users\drakkka\python\Lib\threading.py", line 1045, in _bootstrap_inner
    self.run()
  File "C:\Users\drakkka\python\Lib\threading.py", line 982, in run
    self._target(*self._args, **self._kwargs)
  File "C:\Users\drakkka\Documents\tuber stuff\aigohere\zwaif\z-waif-main\z-waif main new\utils\vtube_studio.py", line 95, in check_emote_string
    run_emote()
  File "C:\Users\drakkka\Documents\tuber stuff\aigohere\zwaif\z-waif-main\z-waif main new\utils\vtube_studio.py", line 99, in run_emote
    asyncio.run(emote())
  File "C:\Users\drakkka\python\Lib\asyncio\runners.py", line 190, in run
    return runner.run(main)
           ^^^^^^^^^^^^^^^^
  File "C:\Users\drakkka\python\Lib\asyncio\runners.py", line 118, in run
    return self._loop.run_until_complete(task)
           ^^^^^^^^^^^^^^^^^^^^^^^^^^^^^^^^^^^
  File "C:\Users\drakkka\python\Lib\asyncio\base_events.py", line 654, in run_until_complete
    return future.result()
           ^^^^^^^^^^^^^^^
  File "C:\Users\drakkka\Documents\tuber stuff\aigohere\zwaif\z-waif-main\z-waif main new\utils\vtube_studio.py", line 102, in emote
    await VTS.connect()
  File "C:\Users\drakkka\Documents\tuber stuff\aigohere\zwaif\z-waif-main\z-waif main new\venv\Lib\site-packages\pyvts\vts.py", line 82, in connect
    self.websocket = await websockets.connect(
                     ^^^^^^^^^^^^^^^^^^^^^^^^^
  File "C:\Users\drakkka\Documents\tuber stuff\aigohere\zwaif\z-waif-main\z-waif main new\venv\Lib\site-packages\websockets\legacy\client.py", line 655, in __await_impl_timeout__
    return await self.__await_impl__()
           ^^^^^^^^^^^^^^^^^^^^^^^^^^^
  File "C:\Users\drakkka\Documents\tuber stuff\aigohere\zwaif\z-waif-main\z-waif main new\venv\Lib\site-packages\websockets\legacy\client.py", line 659, in __await_impl__
    _transport, _protocol = await self._create_connection()
                            ^^^^^^^^^^^^^^^^^^^^^^^^^^^^^^^
  File "C:\Users\drakkka\python\Lib\asyncio\base_events.py", line 1091, in create_connection
    raise exceptions[0]
  File "C:\Users\drakkka\python\Lib\asyncio\base_events.py", line 1070, in create_connection
    sock = await self._connect_sock(
           ^^^^^^^^^^^^^^^^^^^^^^^^^
  File "C:\Users\drakkka\python\Lib\asyncio\base_events.py", line 974, in _connect_sock
    await self.sock_connect(sock, address)
  File "C:\Users\drakkka\python\Lib\asyncio\proactor_events.py", line 726, in sock_connect
    return await self._proactor.connect(sock, address)
           ^^^^^^^^^^^^^^^^^^^^^^^^^^^^^^^^^^^^^^^^^^^
  File "C:\Users\drakkka\python\Lib\asyncio\windows_events.py", line 854, in _poll
    value = callback(transferred, key, ov)
            ^^^^^^^^^^^^^^^^^^^^^^^^^^^^^^
  File "C:\Users\drakkka\python\Lib\asyncio\windows_events.py", line 641, in finish_connect
    ov.getresult()
ConnectionRefusedError: [WinError 1225] The remote computer refused the network connection
[2024-11-04 09:20:59] [INFO    ] discord.gateway: Shard ID None has successfully RESUMED session f6c044669726078b1242fe61183625f0.
[2024-11-04 09:44:52] [INFO    ] discord.gateway: Shard ID None has successfully RESUMED session f6c044669726078b1242fe61183625f0.
Exception in thread Thread-53 (check_emote_string):
Traceback (most recent call last):
  File "C:\Users\drakkka\python\Lib\threading.py", line 1045, in _bootstrap_inner
    self.run()
  File "C:\Users\drakkka\python\Lib\threading.py", line 982, in run
    self._target(*self._args, **self._kwargs)
  File "C:\Users\drakkka\Documents\tuber stuff\aigohere\zwaif\z-waif-main\z-waif main new\utils\vtube_studio.py", line 95, in check_emote_string
    run_emote()
  File "C:\Users\drakkka\Documents\tuber stuff\aigohere\zwaif\z-waif-main\z-waif main new\utils\vtube_studio.py", line 99, in run_emote
    asyncio.run(emote())
  File "C:\Users\drakkka\python\Lib\asyncio\runners.py", line 190, in run
    return runner.run(main)
           ^^^^^^^^^^^^^^^^
  File "C:\Users\drakkka\python\Lib\asyncio\runners.py", line 118, in run
    return self._loop.run_until_complete(task)
           ^^^^^^^^^^^^^^^^^^^^^^^^^^^^^^^^^^^
  File "C:\Users\drakkka\python\Lib\asyncio\base_events.py", line 654, in run_until_complete
    return future.result()
           ^^^^^^^^^^^^^^^
  File "C:\Users\drakkka\Documents\tuber stuff\aigohere\zwaif\z-waif-main\z-waif main new\utils\vtube_studio.py", line 102, in emote
    await VTS.connect()
  File "C:\Users\drakkka\Documents\tuber stuff\aigohere\zwaif\z-waif-main\z-waif main new\venv\Lib\site-packages\pyvts\vts.py", line 82, in connect
    self.websocket = await websockets.connect(
                     ^^^^^^^^^^^^^^^^^^^^^^^^^
  File "C:\Users\drakkka\Documents\tuber stuff\aigohere\zwaif\z-waif-main\z-waif main new\venv\Lib\site-packages\websockets\legacy\client.py", line 655, in __await_impl_timeout__
    return await self.__await_impl__()
           ^^^^^^^^^^^^^^^^^^^^^^^^^^^
  File "C:\Users\drakkka\Documents\tuber stuff\aigohere\zwaif\z-waif-main\z-waif main new\venv\Lib\site-packages\websockets\legacy\client.py", line 659, in __await_impl__
    _transport, _protocol = await self._create_connection()
                            ^^^^^^^^^^^^^^^^^^^^^^^^^^^^^^^
  File "C:\Users\drakkka\python\Lib\asyncio\base_events.py", line 1091, in create_connection
    raise exceptions[0]
  File "C:\Users\drakkka\python\Lib\asyncio\base_events.py", line 1070, in create_connection
    sock = await self._connect_sock(
           ^^^^^^^^^^^^^^^^^^^^^^^^^
  File "C:\Users\drakkka\python\Lib\asyncio\base_events.py", line 974, in _connect_sock
    await self.sock_connect(sock, address)
  File "C:\Users\drakkka\python\Lib\asyncio\proactor_events.py", line 726, in sock_connect
    return await self._proactor.connect(sock, address)
           ^^^^^^^^^^^^^^^^^^^^^^^^^^^^^^^^^^^^^^^^^^^
  File "C:\Users\drakkka\python\Lib\asyncio\windows_events.py", line 854, in _poll
    value = callback(transferred, key, ov)
            ^^^^^^^^^^^^^^^^^^^^^^^^^^^^^^
  File "C:\Users\drakkka\python\Lib\asyncio\windows_events.py", line 641, in finish_connect
    ov.getresult()
ConnectionRefusedError: [WinError 1225] The remote computer refused the network connection

[notice] A new release of pip is available: 24.0 -> 24.3.1
[notice] To update, run: python.exe -m pip install --upgrade pip
  Running command git clone --filter=blob:none --quiet https://github.com/openai/whisper.git 'C:\Users\drakkka\AppData\Local\Temp\pip-req-build-nm_jmuz0'

[notice] A new release of pip is available: 24.0 -> 24.3.1
[notice] To update, run: python.exe -m pip install --upgrade pip

[notice] A new release of pip is available: 24.0 -> 24.3.1
[notice] To update, run: python.exe -m pip install --upgrade pip
[2024-11-05 13:02:41] [INFO    ] discord.client: logging in using static token
[2024-11-05 13:02:42] [INFO    ] discord.gateway: Shard ID None has connected to Gateway (Session ID: 6d5c09d0bf51fffef51c426ad0addfb3).

[notice] A new release of pip is available: 24.0 -> 24.3.1
[notice] To update, run: python.exe -m pip install --upgrade pip
  Running command git clone --filter=blob:none --quiet https://github.com/openai/whisper.git 'C:\Users\drakkka\AppData\Local\Temp\pip-req-build-pn30ufof'

[notice] A new release of pip is available: 24.0 -> 24.3.1
[notice] To update, run: python.exe -m pip install --upgrade pip

[notice] A new release of pip is available: 24.0 -> 24.3.1
[notice] To update, run: python.exe -m pip install --upgrade pip
[2024-11-05 13:07:53] [INFO    ] discord.client: logging in using static token
[2024-11-05 13:07:55] [INFO    ] discord.gateway: Shard ID None has connected to Gateway (Session ID: acc67a4ae758563efce1fd28cd015f8b).
Exception in thread Thread-6 (run_vtube_studio_connection):
Traceback (most recent call last):
  File "C:\Users\drakkka\python\Lib\threading.py", line 1045, in _bootstrap_inner
    self.run()
  File "C:\Users\drakkka\python\Lib\threading.py", line 982, in run
    self._target(*self._args, **self._kwargs)
  File "C:\Users\drakkka\Documents\tuber stuff\aigohere\zwaif\z-waif-main\z-waif main new\utils\vtube_studio.py", line 50, in run_vtube_studio_connection
    asyncio.run(vtube_studio_connection())
  File "C:\Users\drakkka\python\Lib\asyncio\runners.py", line 190, in run
    return runner.run(main)
           ^^^^^^^^^^^^^^^^
  File "C:\Users\drakkka\python\Lib\asyncio\runners.py", line 118, in run
    return self._loop.run_until_complete(task)
           ^^^^^^^^^^^^^^^^^^^^^^^^^^^^^^^^^^^
  File "C:\Users\drakkka\python\Lib\asyncio\base_events.py", line 654, in run_until_complete
    return future.result()
           ^^^^^^^^^^^^^^^
  File "C:\Users\drakkka\Documents\tuber stuff\aigohere\zwaif\z-waif-main\z-waif main new\utils\vtube_studio.py", line 55, in vtube_studio_connection
    await VTS.request_authenticate()
  File "C:\Users\drakkka\Documents\tuber stuff\aigohere\zwaif\z-waif-main\z-waif main new\venv\Lib\site-packages\pyvts\vts.py", line 154, in request_authenticate
    assert responese_dict["data"]["authenticated"], "Authentication Failed"
           ~~~~~~~~~~~~~~~~~~~~~~^^^^^^^^^^^^^^^^^
KeyError: 'authenticated'
Exception in thread Thread-18 (check_emote_string):
Traceback (most recent call last):
  File "C:\Users\drakkka\python\Lib\threading.py", line 1045, in _bootstrap_inner
    self.run()
  File "C:\Users\drakkka\python\Lib\threading.py", line 982, in run
    self._target(*self._args, **self._kwargs)
  File "C:\Users\drakkka\Documents\tuber stuff\aigohere\zwaif\z-waif-main\z-waif main new\utils\vtube_studio.py", line 95, in check_emote_string
    run_emote()
  File "C:\Users\drakkka\Documents\tuber stuff\aigohere\zwaif\z-waif-main\z-waif main new\utils\vtube_studio.py", line 99, in run_emote
    asyncio.run(emote())
  File "C:\Users\drakkka\python\Lib\asyncio\runners.py", line 190, in run
    return runner.run(main)
           ^^^^^^^^^^^^^^^^
  File "C:\Users\drakkka\python\Lib\asyncio\runners.py", line 118, in run
    return self._loop.run_until_complete(task)
           ^^^^^^^^^^^^^^^^^^^^^^^^^^^^^^^^^^^
  File "C:\Users\drakkka\python\Lib\asyncio\base_events.py", line 654, in run_until_complete
    return future.result()
           ^^^^^^^^^^^^^^^
  File "C:\Users\drakkka\Documents\tuber stuff\aigohere\zwaif\z-waif-main\z-waif main new\utils\vtube_studio.py", line 103, in emote
    await VTS.request_authenticate()
  File "C:\Users\drakkka\Documents\tuber stuff\aigohere\zwaif\z-waif-main\z-waif main new\venv\Lib\site-packages\pyvts\vts.py", line 154, in request_authenticate
    assert responese_dict["data"]["authenticated"], "Authentication Failed"
           ~~~~~~~~~~~~~~~~~~~~~~^^^^^^^^^^^^^^^^^
KeyError: 'authenticated'
C:\Users\drakkka\Documents\tuber stuff\aigohere\zwaif\z-waif-main\z-waif main new\venv\Lib\site-packages\whisper\__init__.py:150: FutureWarning: You are using `torch.load` with `weights_only=False` (the current default value), which uses the default pickle module implicitly. It is possible to construct malicious pickle data which will execute arbitrary code during unpickling (See https://github.com/pytorch/pytorch/blob/main/SECURITY.md#untrusted-models for more details). In a future release, the default value for `weights_only` will be flipped to `True`. This limits the functions that could be executed during unpickling. Arbitrary objects will no longer be allowed to be loaded via this mode unless they are explicitly allowlisted by the user via `torch.serialization.add_safe_globals`. We recommend you start setting `weights_only=True` for any use case where you don't have full control of the loaded file. Please open an issue on GitHub for any issues related to this experimental feature.
  checkpoint = torch.load(fp, map_location=device)
Exception in thread Thread-25 (check_emote_string):
Traceback (most recent call last):
  File "C:\Users\drakkka\python\Lib\threading.py", line 1045, in _bootstrap_inner
    self.run()
  File "C:\Users\drakkka\python\Lib\threading.py", line 982, in run
    self._target(*self._args, **self._kwargs)
  File "C:\Users\drakkka\Documents\tuber stuff\aigohere\zwaif\z-waif-main\z-waif main new\utils\vtube_studio.py", line 95, in check_emote_string
    run_emote()
  File "C:\Users\drakkka\Documents\tuber stuff\aigohere\zwaif\z-waif-main\z-waif main new\utils\vtube_studio.py", line 99, in run_emote
    asyncio.run(emote())
  File "C:\Users\drakkka\python\Lib\asyncio\runners.py", line 190, in run
    return runner.run(main)
           ^^^^^^^^^^^^^^^^
  File "C:\Users\drakkka\python\Lib\asyncio\runners.py", line 118, in run
    return self._loop.run_until_complete(task)
           ^^^^^^^^^^^^^^^^^^^^^^^^^^^^^^^^^^^
  File "C:\Users\drakkka\python\Lib\asyncio\base_events.py", line 654, in run_until_complete
    return future.result()
           ^^^^^^^^^^^^^^^
  File "C:\Users\drakkka\Documents\tuber stuff\aigohere\zwaif\z-waif-main\z-waif main new\utils\vtube_studio.py", line 103, in emote
    await VTS.request_authenticate()
  File "C:\Users\drakkka\Documents\tuber stuff\aigohere\zwaif\z-waif-main\z-waif main new\venv\Lib\site-packages\pyvts\vts.py", line 154, in request_authenticate
    assert responese_dict["data"]["authenticated"], "Authentication Failed"
           ~~~~~~~~~~~~~~~~~~~~~~^^^^^^^^^^^^^^^^^
KeyError: 'authenticated'
Exception in thread Thread-28 (check_emote_string):
Traceback (most recent call last):
  File "C:\Users\drakkka\python\Lib\threading.py", line 1045, in _bootstrap_inner
    self.run()
  File "C:\Users\drakkka\python\Lib\threading.py", line 982, in run
    self._target(*self._args, **self._kwargs)
  File "C:\Users\drakkka\Documents\tuber stuff\aigohere\zwaif\z-waif-main\z-waif main new\utils\vtube_studio.py", line 95, in check_emote_string
    run_emote()
  File "C:\Users\drakkka\Documents\tuber stuff\aigohere\zwaif\z-waif-main\z-waif main new\utils\vtube_studio.py", line 99, in run_emote
    asyncio.run(emote())
  File "C:\Users\drakkka\python\Lib\asyncio\runners.py", line 190, in run
    return runner.run(main)
           ^^^^^^^^^^^^^^^^
  File "C:\Users\drakkka\python\Lib\asyncio\runners.py", line 118, in run
    return self._loop.run_until_complete(task)
           ^^^^^^^^^^^^^^^^^^^^^^^^^^^^^^^^^^^
  File "C:\Users\drakkka\python\Lib\asyncio\base_events.py", line 654, in run_until_complete
    return future.result()
           ^^^^^^^^^^^^^^^
  File "C:\Users\drakkka\Documents\tuber stuff\aigohere\zwaif\z-waif-main\z-waif main new\utils\vtube_studio.py", line 103, in emote
    await VTS.request_authenticate()
  File "C:\Users\drakkka\Documents\tuber stuff\aigohere\zwaif\z-waif-main\z-waif main new\venv\Lib\site-packages\pyvts\vts.py", line 154, in request_authenticate
    assert responese_dict["data"]["authenticated"], "Authentication Failed"
           ~~~~~~~~~~~~~~~~~~~~~~^^^^^^^^^^^^^^^^^
KeyError: 'authenticated'
Exception in thread Thread-34 (check_emote_string):
Traceback (most recent call last):
  File "C:\Users\drakkka\python\Lib\threading.py", line 1045, in _bootstrap_inner
    self.run()
  File "C:\Users\drakkka\python\Lib\threading.py", line 982, in run
    self._target(*self._args, **self._kwargs)
  File "C:\Users\drakkka\Documents\tuber stuff\aigohere\zwaif\z-waif-main\z-waif main new\utils\vtube_studio.py", line 95, in check_emote_string
    run_emote()
  File "C:\Users\drakkka\Documents\tuber stuff\aigohere\zwaif\z-waif-main\z-waif main new\utils\vtube_studio.py", line 99, in run_emote
    asyncio.run(emote())
  File "C:\Users\drakkka\python\Lib\asyncio\runners.py", line 190, in run
    return runner.run(main)
           ^^^^^^^^^^^^^^^^
  File "C:\Users\drakkka\python\Lib\asyncio\runners.py", line 118, in run
    return self._loop.run_until_complete(task)
           ^^^^^^^^^^^^^^^^^^^^^^^^^^^^^^^^^^^
  File "C:\Users\drakkka\python\Lib\asyncio\base_events.py", line 654, in run_until_complete
    return future.result()
           ^^^^^^^^^^^^^^^
  File "C:\Users\drakkka\Documents\tuber stuff\aigohere\zwaif\z-waif-main\z-waif main new\utils\vtube_studio.py", line 103, in emote
    await VTS.request_authenticate()
  File "C:\Users\drakkka\Documents\tuber stuff\aigohere\zwaif\z-waif-main\z-waif main new\venv\Lib\site-packages\pyvts\vts.py", line 154, in request_authenticate
    assert responese_dict["data"]["authenticated"], "Authentication Failed"
           ~~~~~~~~~~~~~~~~~~~~~~^^^^^^^^^^^^^^^^^
KeyError: 'authenticated'
Exception in thread Thread-36 (check_emote_string):
Traceback (most recent call last):
  File "C:\Users\drakkka\python\Lib\threading.py", line 1045, in _bootstrap_inner
    self.run()
  File "C:\Users\drakkka\python\Lib\threading.py", line 982, in run
    self._target(*self._args, **self._kwargs)
  File "C:\Users\drakkka\Documents\tuber stuff\aigohere\zwaif\z-waif-main\z-waif main new\utils\vtube_studio.py", line 95, in check_emote_string
    run_emote()
  File "C:\Users\drakkka\Documents\tuber stuff\aigohere\zwaif\z-waif-main\z-waif main new\utils\vtube_studio.py", line 99, in run_emote
    asyncio.run(emote())
  File "C:\Users\drakkka\python\Lib\asyncio\runners.py", line 190, in run
    return runner.run(main)
           ^^^^^^^^^^^^^^^^
  File "C:\Users\drakkka\python\Lib\asyncio\runners.py", line 118, in run
    return self._loop.run_until_complete(task)
           ^^^^^^^^^^^^^^^^^^^^^^^^^^^^^^^^^^^
  File "C:\Users\drakkka\python\Lib\asyncio\base_events.py", line 654, in run_until_complete
    return future.result()
           ^^^^^^^^^^^^^^^
  File "C:\Users\drakkka\Documents\tuber stuff\aigohere\zwaif\z-waif-main\z-waif main new\utils\vtube_studio.py", line 103, in emote
    await VTS.request_authenticate()
  File "C:\Users\drakkka\Documents\tuber stuff\aigohere\zwaif\z-waif-main\z-waif main new\venv\Lib\site-packages\pyvts\vts.py", line 154, in request_authenticate
    assert responese_dict["data"]["authenticated"], "Authentication Failed"
           ~~~~~~~~~~~~~~~~~~~~~~^^^^^^^^^^^^^^^^^
KeyError: 'authenticated'
Exception in thread Thread-39 (check_emote_string):
Traceback (most recent call last):
  File "C:\Users\drakkka\python\Lib\threading.py", line 1045, in _bootstrap_inner
    self.run()
  File "C:\Users\drakkka\python\Lib\threading.py", line 982, in run
    self._target(*self._args, **self._kwargs)
  File "C:\Users\drakkka\Documents\tuber stuff\aigohere\zwaif\z-waif-main\z-waif main new\utils\vtube_studio.py", line 95, in check_emote_string
    run_emote()
  File "C:\Users\drakkka\Documents\tuber stuff\aigohere\zwaif\z-waif-main\z-waif main new\utils\vtube_studio.py", line 99, in run_emote
    asyncio.run(emote())
  File "C:\Users\drakkka\python\Lib\asyncio\runners.py", line 190, in run
    return runner.run(main)
           ^^^^^^^^^^^^^^^^
  File "C:\Users\drakkka\python\Lib\asyncio\runners.py", line 118, in run
    return self._loop.run_until_complete(task)
           ^^^^^^^^^^^^^^^^^^^^^^^^^^^^^^^^^^^
  File "C:\Users\drakkka\python\Lib\asyncio\base_events.py", line 654, in run_until_complete
    return future.result()
           ^^^^^^^^^^^^^^^
  File "C:\Users\drakkka\Documents\tuber stuff\aigohere\zwaif\z-waif-main\z-waif main new\utils\vtube_studio.py", line 103, in emote
    await VTS.request_authenticate()
  File "C:\Users\drakkka\Documents\tuber stuff\aigohere\zwaif\z-waif-main\z-waif main new\venv\Lib\site-packages\pyvts\vts.py", line 154, in request_authenticate
    assert responese_dict["data"]["authenticated"], "Authentication Failed"
           ~~~~~~~~~~~~~~~~~~~~~~^^^^^^^^^^^^^^^^^
KeyError: 'authenticated'
[2024-11-05 13:56:35] [INFO    ] discord.gateway: Shard ID None has successfully RESUMED session acc67a4ae758563efce1fd28cd015f8b.
[2024-11-05 17:23:20] [INFO    ] discord.gateway: Shard ID None has successfully RESUMED session acc67a4ae758563efce1fd28cd015f8b.
[2024-11-05 19:41:38] [INFO    ] discord.gateway: Shard ID None has successfully RESUMED session acc67a4ae758563efce1fd28cd015f8b.
[2024-11-05 23:15:54] [INFO    ] discord.gateway: Shard ID None has successfully RESUMED session acc67a4ae758563efce1fd28cd015f8b.
[2024-11-06 01:14:47] [INFO    ] discord.gateway: Shard ID None has successfully RESUMED session acc67a4ae758563efce1fd28cd015f8b.
[2024-11-06 01:57:21] [INFO    ] discord.gateway: Shard ID None has successfully RESUMED session acc67a4ae758563efce1fd28cd015f8b.
Exception in thread Thread-47 (check_emote_string):
Traceback (most recent call last):
  File "C:\Users\drakkka\python\Lib\threading.py", line 1045, in _bootstrap_inner
    self.run()
  File "C:\Users\drakkka\python\Lib\threading.py", line 982, in run
    self._target(*self._args, **self._kwargs)
  File "C:\Users\drakkka\Documents\tuber stuff\aigohere\zwaif\z-waif-main\z-waif main new\utils\vtube_studio.py", line 95, in check_emote_string
    run_emote()
  File "C:\Users\drakkka\Documents\tuber stuff\aigohere\zwaif\z-waif-main\z-waif main new\utils\vtube_studio.py", line 99, in run_emote
    asyncio.run(emote())
  File "C:\Users\drakkka\python\Lib\asyncio\runners.py", line 190, in run
    return runner.run(main)
           ^^^^^^^^^^^^^^^^
  File "C:\Users\drakkka\python\Lib\asyncio\runners.py", line 118, in run
    return self._loop.run_until_complete(task)
           ^^^^^^^^^^^^^^^^^^^^^^^^^^^^^^^^^^^
  File "C:\Users\drakkka\python\Lib\asyncio\base_events.py", line 654, in run_until_complete
    return future.result()
           ^^^^^^^^^^^^^^^
  File "C:\Users\drakkka\Documents\tuber stuff\aigohere\zwaif\z-waif-main\z-waif main new\utils\vtube_studio.py", line 102, in emote
    await VTS.connect()
  File "C:\Users\drakkka\Documents\tuber stuff\aigohere\zwaif\z-waif-main\z-waif main new\venv\Lib\site-packages\pyvts\vts.py", line 82, in connect
    self.websocket = await websockets.connect(
                     ^^^^^^^^^^^^^^^^^^^^^^^^^
  File "C:\Users\drakkka\Documents\tuber stuff\aigohere\zwaif\z-waif-main\z-waif main new\venv\Lib\site-packages\websockets\legacy\client.py", line 655, in __await_impl_timeout__
    return await self.__await_impl__()
           ^^^^^^^^^^^^^^^^^^^^^^^^^^^
  File "C:\Users\drakkka\Documents\tuber stuff\aigohere\zwaif\z-waif-main\z-waif main new\venv\Lib\site-packages\websockets\legacy\client.py", line 659, in __await_impl__
    _transport, _protocol = await self._create_connection()
                            ^^^^^^^^^^^^^^^^^^^^^^^^^^^^^^^
  File "C:\Users\drakkka\python\Lib\asyncio\base_events.py", line 1091, in create_connection
    raise exceptions[0]
  File "C:\Users\drakkka\python\Lib\asyncio\base_events.py", line 1070, in create_connection
    sock = await self._connect_sock(
           ^^^^^^^^^^^^^^^^^^^^^^^^^
  File "C:\Users\drakkka\python\Lib\asyncio\base_events.py", line 974, in _connect_sock
    await self.sock_connect(sock, address)
  File "C:\Users\drakkka\python\Lib\asyncio\proactor_events.py", line 726, in sock_connect
    return await self._proactor.connect(sock, address)
           ^^^^^^^^^^^^^^^^^^^^^^^^^^^^^^^^^^^^^^^^^^^
  File "C:\Users\drakkka\python\Lib\asyncio\windows_events.py", line 854, in _poll
    value = callback(transferred, key, ov)
            ^^^^^^^^^^^^^^^^^^^^^^^^^^^^^^
  File "C:\Users\drakkka\python\Lib\asyncio\windows_events.py", line 641, in finish_connect
    ov.getresult()
ConnectionRefusedError: [WinError 1225] The remote computer refused the network connection
[2024-11-06 03:21:03] [INFO    ] discord.gateway: Shard ID None has successfully RESUMED session acc67a4ae758563efce1fd28cd015f8b.
[2024-11-06 05:06:58] [INFO    ] discord.gateway: Shard ID None has successfully RESUMED session acc67a4ae758563efce1fd28cd015f8b.
[2024-11-06 05:08:51] [INFO    ] discord.gateway: Shard ID None has successfully RESUMED session acc67a4ae758563efce1fd28cd015f8b.
[2024-11-06 05:10:45] [INFO    ] discord.gateway: Shard ID None has successfully RESUMED session acc67a4ae758563efce1fd28cd015f8b.
[2024-11-06 05:35:30] [INFO    ] discord.gateway: Shard ID None has successfully RESUMED session acc67a4ae758563efce1fd28cd015f8b.
[2024-11-06 05:38:46] [INFO    ] discord.gateway: Shard ID None has successfully RESUMED session acc67a4ae758563efce1fd28cd015f8b.
[2024-11-06 06:00:36] [INFO    ] discord.gateway: Shard ID None has successfully RESUMED session acc67a4ae758563efce1fd28cd015f8b.
[2024-11-06 06:03:22] [INFO    ] discord.gateway: Shard ID None has successfully RESUMED session acc67a4ae758563efce1fd28cd015f8b.
[2024-11-06 06:25:53] [INFO    ] discord.gateway: Shard ID None has successfully RESUMED session acc67a4ae758563efce1fd28cd015f8b.
[2024-11-06 06:29:08] [INFO    ] discord.gateway: Shard ID None has successfully RESUMED session acc67a4ae758563efce1fd28cd015f8b.
Exception in thread Thread-49 (check_emote_string):
Traceback (most recent call last):
  File "C:\Users\drakkka\python\Lib\threading.py", line 1045, in _bootstrap_inner
    self.run()
  File "C:\Users\drakkka\python\Lib\threading.py", line 982, in run
    self._target(*self._args, **self._kwargs)
  File "C:\Users\drakkka\Documents\tuber stuff\aigohere\zwaif\z-waif-main\z-waif main new\utils\vtube_studio.py", line 95, in check_emote_string
    run_emote()
  File "C:\Users\drakkka\Documents\tuber stuff\aigohere\zwaif\z-waif-main\z-waif main new\utils\vtube_studio.py", line 99, in run_emote
    asyncio.run(emote())
  File "C:\Users\drakkka\python\Lib\asyncio\runners.py", line 190, in run
    return runner.run(main)
           ^^^^^^^^^^^^^^^^
  File "C:\Users\drakkka\python\Lib\asyncio\runners.py", line 118, in run
    return self._loop.run_until_complete(task)
           ^^^^^^^^^^^^^^^^^^^^^^^^^^^^^^^^^^^
  File "C:\Users\drakkka\python\Lib\asyncio\base_events.py", line 654, in run_until_complete
    return future.result()
           ^^^^^^^^^^^^^^^
  File "C:\Users\drakkka\Documents\tuber stuff\aigohere\zwaif\z-waif-main\z-waif main new\utils\vtube_studio.py", line 102, in emote
    await VTS.connect()
  File "C:\Users\drakkka\Documents\tuber stuff\aigohere\zwaif\z-waif-main\z-waif main new\venv\Lib\site-packages\pyvts\vts.py", line 82, in connect
    self.websocket = await websockets.connect(
                     ^^^^^^^^^^^^^^^^^^^^^^^^^
  File "C:\Users\drakkka\Documents\tuber stuff\aigohere\zwaif\z-waif-main\z-waif main new\venv\Lib\site-packages\websockets\legacy\client.py", line 655, in __await_impl_timeout__
    return await self.__await_impl__()
           ^^^^^^^^^^^^^^^^^^^^^^^^^^^
  File "C:\Users\drakkka\Documents\tuber stuff\aigohere\zwaif\z-waif-main\z-waif main new\venv\Lib\site-packages\websockets\legacy\client.py", line 659, in __await_impl__
    _transport, _protocol = await self._create_connection()
                            ^^^^^^^^^^^^^^^^^^^^^^^^^^^^^^^
  File "C:\Users\drakkka\python\Lib\asyncio\base_events.py", line 1091, in create_connection
    raise exceptions[0]
  File "C:\Users\drakkka\python\Lib\asyncio\base_events.py", line 1070, in create_connection
    sock = await self._connect_sock(
           ^^^^^^^^^^^^^^^^^^^^^^^^^
  File "C:\Users\drakkka\python\Lib\asyncio\base_events.py", line 974, in _connect_sock
    await self.sock_connect(sock, address)
  File "C:\Users\drakkka\python\Lib\asyncio\proactor_events.py", line 726, in sock_connect
    return await self._proactor.connect(sock, address)
           ^^^^^^^^^^^^^^^^^^^^^^^^^^^^^^^^^^^^^^^^^^^
  File "C:\Users\drakkka\python\Lib\asyncio\windows_events.py", line 854, in _poll
    value = callback(transferred, key, ov)
            ^^^^^^^^^^^^^^^^^^^^^^^^^^^^^^
  File "C:\Users\drakkka\python\Lib\asyncio\windows_events.py", line 641, in finish_connect
    ov.getresult()
ConnectionRefusedError: [WinError 1225] The remote computer refused the network connection
[2024-11-06 10:08:30] [INFO    ] discord.gateway: Shard ID None has successfully RESUMED session acc67a4ae758563efce1fd28cd015f8b.
Exception in thread Thread-51 (check_emote_string):
Traceback (most recent call last):
  File "C:\Users\drakkka\python\Lib\threading.py", line 1045, in _bootstrap_inner
    self.run()
  File "C:\Users\drakkka\python\Lib\threading.py", line 982, in run
    self._target(*self._args, **self._kwargs)
  File "C:\Users\drakkka\Documents\tuber stuff\aigohere\zwaif\z-waif-main\z-waif main new\utils\vtube_studio.py", line 95, in check_emote_string
    run_emote()
  File "C:\Users\drakkka\Documents\tuber stuff\aigohere\zwaif\z-waif-main\z-waif main new\utils\vtube_studio.py", line 99, in run_emote
    asyncio.run(emote())
  File "C:\Users\drakkka\python\Lib\asyncio\runners.py", line 190, in run
    return runner.run(main)
           ^^^^^^^^^^^^^^^^
  File "C:\Users\drakkka\python\Lib\asyncio\runners.py", line 118, in run
    return self._loop.run_until_complete(task)
           ^^^^^^^^^^^^^^^^^^^^^^^^^^^^^^^^^^^
  File "C:\Users\drakkka\python\Lib\asyncio\base_events.py", line 654, in run_until_complete
    return future.result()
           ^^^^^^^^^^^^^^^
  File "C:\Users\drakkka\Documents\tuber stuff\aigohere\zwaif\z-waif-main\z-waif main new\utils\vtube_studio.py", line 102, in emote
    await VTS.connect()
  File "C:\Users\drakkka\Documents\tuber stuff\aigohere\zwaif\z-waif-main\z-waif main new\venv\Lib\site-packages\pyvts\vts.py", line 82, in connect
    self.websocket = await websockets.connect(
                     ^^^^^^^^^^^^^^^^^^^^^^^^^
  File "C:\Users\drakkka\Documents\tuber stuff\aigohere\zwaif\z-waif-main\z-waif main new\venv\Lib\site-packages\websockets\legacy\client.py", line 655, in __await_impl_timeout__
    return await self.__await_impl__()
           ^^^^^^^^^^^^^^^^^^^^^^^^^^^
  File "C:\Users\drakkka\Documents\tuber stuff\aigohere\zwaif\z-waif-main\z-waif main new\venv\Lib\site-packages\websockets\legacy\client.py", line 659, in __await_impl__
    _transport, _protocol = await self._create_connection()
                            ^^^^^^^^^^^^^^^^^^^^^^^^^^^^^^^
  File "C:\Users\drakkka\python\Lib\asyncio\base_events.py", line 1091, in create_connection
    raise exceptions[0]
  File "C:\Users\drakkka\python\Lib\asyncio\base_events.py", line 1070, in create_connection
    sock = await self._connect_sock(
           ^^^^^^^^^^^^^^^^^^^^^^^^^
  File "C:\Users\drakkka\python\Lib\asyncio\base_events.py", line 974, in _connect_sock
    await self.sock_connect(sock, address)
  File "C:\Users\drakkka\python\Lib\asyncio\proactor_events.py", line 726, in sock_connect
    return await self._proactor.connect(sock, address)
           ^^^^^^^^^^^^^^^^^^^^^^^^^^^^^^^^^^^^^^^^^^^
  File "C:\Users\drakkka\python\Lib\asyncio\windows_events.py", line 854, in _poll
    value = callback(transferred, key, ov)
            ^^^^^^^^^^^^^^^^^^^^^^^^^^^^^^
  File "C:\Users\drakkka\python\Lib\asyncio\windows_events.py", line 641, in finish_connect
    ov.getresult()
ConnectionRefusedError: [WinError 1225] The remote computer refused the network connection
[2024-11-06 13:26:25] [INFO    ] discord.gateway: Shard ID None has successfully RESUMED session acc67a4ae758563efce1fd28cd015f8b.
Exception in thread Thread-53 (check_emote_string):
Traceback (most recent call last):
  File "C:\Users\drakkka\python\Lib\threading.py", line 1045, in _bootstrap_inner
    self.run()
  File "C:\Users\drakkka\python\Lib\threading.py", line 982, in run
    self._target(*self._args, **self._kwargs)
  File "C:\Users\drakkka\Documents\tuber stuff\aigohere\zwaif\z-waif-main\z-waif main new\utils\vtube_studio.py", line 95, in check_emote_string
    run_emote()
  File "C:\Users\drakkka\Documents\tuber stuff\aigohere\zwaif\z-waif-main\z-waif main new\utils\vtube_studio.py", line 99, in run_emote
    asyncio.run(emote())
  File "C:\Users\drakkka\python\Lib\asyncio\runners.py", line 190, in run
    return runner.run(main)
           ^^^^^^^^^^^^^^^^
  File "C:\Users\drakkka\python\Lib\asyncio\runners.py", line 118, in run
    return self._loop.run_until_complete(task)
           ^^^^^^^^^^^^^^^^^^^^^^^^^^^^^^^^^^^
  File "C:\Users\drakkka\python\Lib\asyncio\base_events.py", line 654, in run_until_complete
    return future.result()
           ^^^^^^^^^^^^^^^
  File "C:\Users\drakkka\Documents\tuber stuff\aigohere\zwaif\z-waif-main\z-waif main new\utils\vtube_studio.py", line 102, in emote
    await VTS.connect()
  File "C:\Users\drakkka\Documents\tuber stuff\aigohere\zwaif\z-waif-main\z-waif main new\venv\Lib\site-packages\pyvts\vts.py", line 82, in connect
    self.websocket = await websockets.connect(
                     ^^^^^^^^^^^^^^^^^^^^^^^^^
  File "C:\Users\drakkka\Documents\tuber stuff\aigohere\zwaif\z-waif-main\z-waif main new\venv\Lib\site-packages\websockets\legacy\client.py", line 655, in __await_impl_timeout__
    return await self.__await_impl__()
           ^^^^^^^^^^^^^^^^^^^^^^^^^^^
  File "C:\Users\drakkka\Documents\tuber stuff\aigohere\zwaif\z-waif-main\z-waif main new\venv\Lib\site-packages\websockets\legacy\client.py", line 659, in __await_impl__
    _transport, _protocol = await self._create_connection()
                            ^^^^^^^^^^^^^^^^^^^^^^^^^^^^^^^
  File "C:\Users\drakkka\python\Lib\asyncio\base_events.py", line 1091, in create_connection
    raise exceptions[0]
  File "C:\Users\drakkka\python\Lib\asyncio\base_events.py", line 1070, in create_connection
    sock = await self._connect_sock(
           ^^^^^^^^^^^^^^^^^^^^^^^^^
  File "C:\Users\drakkka\python\Lib\asyncio\base_events.py", line 974, in _connect_sock
    await self.sock_connect(sock, address)
  File "C:\Users\drakkka\python\Lib\asyncio\proactor_events.py", line 726, in sock_connect
    return await self._proactor.connect(sock, address)
           ^^^^^^^^^^^^^^^^^^^^^^^^^^^^^^^^^^^^^^^^^^^
  File "C:\Users\drakkka\python\Lib\asyncio\windows_events.py", line 854, in _poll
    value = callback(transferred, key, ov)
            ^^^^^^^^^^^^^^^^^^^^^^^^^^^^^^
  File "C:\Users\drakkka\python\Lib\asyncio\windows_events.py", line 641, in finish_connect
    ov.getresult()
ConnectionRefusedError: [WinError 1225] The remote computer refused the network connection
Exception in thread Thread-55 (check_emote_string):
Traceback (most recent call last):
  File "C:\Users\drakkka\python\Lib\threading.py", line 1045, in _bootstrap_inner
    self.run()
  File "C:\Users\drakkka\python\Lib\threading.py", line 982, in run
    self._target(*self._args, **self._kwargs)
  File "C:\Users\drakkka\Documents\tuber stuff\aigohere\zwaif\z-waif-main\z-waif main new\utils\vtube_studio.py", line 95, in check_emote_string
    run_emote()
  File "C:\Users\drakkka\Documents\tuber stuff\aigohere\zwaif\z-waif-main\z-waif main new\utils\vtube_studio.py", line 99, in run_emote
    asyncio.run(emote())
  File "C:\Users\drakkka\python\Lib\asyncio\runners.py", line 190, in run
    return runner.run(main)
           ^^^^^^^^^^^^^^^^
  File "C:\Users\drakkka\python\Lib\asyncio\runners.py", line 118, in run
    return self._loop.run_until_complete(task)
           ^^^^^^^^^^^^^^^^^^^^^^^^^^^^^^^^^^^
  File "C:\Users\drakkka\python\Lib\asyncio\base_events.py", line 654, in run_until_complete
    return future.result()
           ^^^^^^^^^^^^^^^
  File "C:\Users\drakkka\Documents\tuber stuff\aigohere\zwaif\z-waif-main\z-waif main new\utils\vtube_studio.py", line 102, in emote
    await VTS.connect()
  File "C:\Users\drakkka\Documents\tuber stuff\aigohere\zwaif\z-waif-main\z-waif main new\venv\Lib\site-packages\pyvts\vts.py", line 82, in connect
    self.websocket = await websockets.connect(
                     ^^^^^^^^^^^^^^^^^^^^^^^^^
  File "C:\Users\drakkka\Documents\tuber stuff\aigohere\zwaif\z-waif-main\z-waif main new\venv\Lib\site-packages\websockets\legacy\client.py", line 655, in __await_impl_timeout__
    return await self.__await_impl__()
           ^^^^^^^^^^^^^^^^^^^^^^^^^^^
  File "C:\Users\drakkka\Documents\tuber stuff\aigohere\zwaif\z-waif-main\z-waif main new\venv\Lib\site-packages\websockets\legacy\client.py", line 659, in __await_impl__
    _transport, _protocol = await self._create_connection()
                            ^^^^^^^^^^^^^^^^^^^^^^^^^^^^^^^
  File "C:\Users\drakkka\python\Lib\asyncio\base_events.py", line 1091, in create_connection
    raise exceptions[0]
  File "C:\Users\drakkka\python\Lib\asyncio\base_events.py", line 1070, in create_connection
    sock = await self._connect_sock(
           ^^^^^^^^^^^^^^^^^^^^^^^^^
  File "C:\Users\drakkka\python\Lib\asyncio\base_events.py", line 974, in _connect_sock
    await self.sock_connect(sock, address)
  File "C:\Users\drakkka\python\Lib\asyncio\proactor_events.py", line 726, in sock_connect
    return await self._proactor.connect(sock, address)
           ^^^^^^^^^^^^^^^^^^^^^^^^^^^^^^^^^^^^^^^^^^^
  File "C:\Users\drakkka\python\Lib\asyncio\windows_events.py", line 854, in _poll
    value = callback(transferred, key, ov)
            ^^^^^^^^^^^^^^^^^^^^^^^^^^^^^^
  File "C:\Users\drakkka\python\Lib\asyncio\windows_events.py", line 641, in finish_connect
    ov.getresult()
ConnectionRefusedError: [WinError 1225] The remote computer refused the network connection
Exception in thread Thread-57 (check_emote_string):
Traceback (most recent call last):
  File "C:\Users\drakkka\python\Lib\threading.py", line 1045, in _bootstrap_inner
    self.run()
  File "C:\Users\drakkka\python\Lib\threading.py", line 982, in run
    self._target(*self._args, **self._kwargs)
  File "C:\Users\drakkka\Documents\tuber stuff\aigohere\zwaif\z-waif-main\z-waif main new\utils\vtube_studio.py", line 95, in check_emote_string
    run_emote()
  File "C:\Users\drakkka\Documents\tuber stuff\aigohere\zwaif\z-waif-main\z-waif main new\utils\vtube_studio.py", line 99, in run_emote
    asyncio.run(emote())
  File "C:\Users\drakkka\python\Lib\asyncio\runners.py", line 190, in run
    return runner.run(main)
           ^^^^^^^^^^^^^^^^
  File "C:\Users\drakkka\python\Lib\asyncio\runners.py", line 118, in run
    return self._loop.run_until_complete(task)
           ^^^^^^^^^^^^^^^^^^^^^^^^^^^^^^^^^^^
  File "C:\Users\drakkka\python\Lib\asyncio\base_events.py", line 654, in run_until_complete
    return future.result()
           ^^^^^^^^^^^^^^^
  File "C:\Users\drakkka\Documents\tuber stuff\aigohere\zwaif\z-waif-main\z-waif main new\utils\vtube_studio.py", line 102, in emote
    await VTS.connect()
  File "C:\Users\drakkka\Documents\tuber stuff\aigohere\zwaif\z-waif-main\z-waif main new\venv\Lib\site-packages\pyvts\vts.py", line 82, in connect
    self.websocket = await websockets.connect(
                     ^^^^^^^^^^^^^^^^^^^^^^^^^
  File "C:\Users\drakkka\Documents\tuber stuff\aigohere\zwaif\z-waif-main\z-waif main new\venv\Lib\site-packages\websockets\legacy\client.py", line 655, in __await_impl_timeout__
    return await self.__await_impl__()
           ^^^^^^^^^^^^^^^^^^^^^^^^^^^
  File "C:\Users\drakkka\Documents\tuber stuff\aigohere\zwaif\z-waif-main\z-waif main new\venv\Lib\site-packages\websockets\legacy\client.py", line 659, in __await_impl__
    _transport, _protocol = await self._create_connection()
                            ^^^^^^^^^^^^^^^^^^^^^^^^^^^^^^^
  File "C:\Users\drakkka\python\Lib\asyncio\base_events.py", line 1091, in create_connection
    raise exceptions[0]
  File "C:\Users\drakkka\python\Lib\asyncio\base_events.py", line 1070, in create_connection
    sock = await self._connect_sock(
           ^^^^^^^^^^^^^^^^^^^^^^^^^
  File "C:\Users\drakkka\python\Lib\asyncio\base_events.py", line 974, in _connect_sock
    await self.sock_connect(sock, address)
  File "C:\Users\drakkka\python\Lib\asyncio\proactor_events.py", line 726, in sock_connect
    return await self._proactor.connect(sock, address)
           ^^^^^^^^^^^^^^^^^^^^^^^^^^^^^^^^^^^^^^^^^^^
  File "C:\Users\drakkka\python\Lib\asyncio\windows_events.py", line 854, in _poll
    value = callback(transferred, key, ov)
            ^^^^^^^^^^^^^^^^^^^^^^^^^^^^^^
  File "C:\Users\drakkka\python\Lib\asyncio\windows_events.py", line 641, in finish_connect
    ov.getresult()
ConnectionRefusedError: [WinError 1225] The remote computer refused the network connection
Exception in thread Thread-59 (check_emote_string):
Traceback (most recent call last):
  File "C:\Users\drakkka\python\Lib\threading.py", line 1045, in _bootstrap_inner
    self.run()
  File "C:\Users\drakkka\python\Lib\threading.py", line 982, in run
    self._target(*self._args, **self._kwargs)
  File "C:\Users\drakkka\Documents\tuber stuff\aigohere\zwaif\z-waif-main\z-waif main new\utils\vtube_studio.py", line 95, in check_emote_string
    run_emote()
  File "C:\Users\drakkka\Documents\tuber stuff\aigohere\zwaif\z-waif-main\z-waif main new\utils\vtube_studio.py", line 99, in run_emote
    asyncio.run(emote())
  File "C:\Users\drakkka\python\Lib\asyncio\runners.py", line 190, in run
    return runner.run(main)
           ^^^^^^^^^^^^^^^^
  File "C:\Users\drakkka\python\Lib\asyncio\runners.py", line 118, in run
    return self._loop.run_until_complete(task)
           ^^^^^^^^^^^^^^^^^^^^^^^^^^^^^^^^^^^
  File "C:\Users\drakkka\python\Lib\asyncio\base_events.py", line 654, in run_until_complete
    return future.result()
           ^^^^^^^^^^^^^^^
  File "C:\Users\drakkka\Documents\tuber stuff\aigohere\zwaif\z-waif-main\z-waif main new\utils\vtube_studio.py", line 102, in emote
    await VTS.connect()
  File "C:\Users\drakkka\Documents\tuber stuff\aigohere\zwaif\z-waif-main\z-waif main new\venv\Lib\site-packages\pyvts\vts.py", line 82, in connect
    self.websocket = await websockets.connect(
                     ^^^^^^^^^^^^^^^^^^^^^^^^^
  File "C:\Users\drakkka\Documents\tuber stuff\aigohere\zwaif\z-waif-main\z-waif main new\venv\Lib\site-packages\websockets\legacy\client.py", line 655, in __await_impl_timeout__
    return await self.__await_impl__()
           ^^^^^^^^^^^^^^^^^^^^^^^^^^^
  File "C:\Users\drakkka\Documents\tuber stuff\aigohere\zwaif\z-waif-main\z-waif main new\venv\Lib\site-packages\websockets\legacy\client.py", line 659, in __await_impl__
    _transport, _protocol = await self._create_connection()
                            ^^^^^^^^^^^^^^^^^^^^^^^^^^^^^^^
  File "C:\Users\drakkka\python\Lib\asyncio\base_events.py", line 1091, in create_connection
    raise exceptions[0]
  File "C:\Users\drakkka\python\Lib\asyncio\base_events.py", line 1070, in create_connection
    sock = await self._connect_sock(
           ^^^^^^^^^^^^^^^^^^^^^^^^^
  File "C:\Users\drakkka\python\Lib\asyncio\base_events.py", line 974, in _connect_sock
    await self.sock_connect(sock, address)
  File "C:\Users\drakkka\python\Lib\asyncio\proactor_events.py", line 726, in sock_connect
    return await self._proactor.connect(sock, address)
           ^^^^^^^^^^^^^^^^^^^^^^^^^^^^^^^^^^^^^^^^^^^
  File "C:\Users\drakkka\python\Lib\asyncio\windows_events.py", line 854, in _poll
    value = callback(transferred, key, ov)
            ^^^^^^^^^^^^^^^^^^^^^^^^^^^^^^
  File "C:\Users\drakkka\python\Lib\asyncio\windows_events.py", line 641, in finish_connect
    ov.getresult()
ConnectionRefusedError: [WinError 1225] The remote computer refused the network connection
Exception in thread Thread-61 (check_emote_string):
Traceback (most recent call last):
  File "C:\Users\drakkka\python\Lib\threading.py", line 1045, in _bootstrap_inner
    self.run()
  File "C:\Users\drakkka\python\Lib\threading.py", line 982, in run
    self._target(*self._args, **self._kwargs)
  File "C:\Users\drakkka\Documents\tuber stuff\aigohere\zwaif\z-waif-main\z-waif main new\utils\vtube_studio.py", line 95, in check_emote_string
    run_emote()
  File "C:\Users\drakkka\Documents\tuber stuff\aigohere\zwaif\z-waif-main\z-waif main new\utils\vtube_studio.py", line 99, in run_emote
    asyncio.run(emote())
  File "C:\Users\drakkka\python\Lib\asyncio\runners.py", line 190, in run
    return runner.run(main)
           ^^^^^^^^^^^^^^^^
  File "C:\Users\drakkka\python\Lib\asyncio\runners.py", line 118, in run
    return self._loop.run_until_complete(task)
           ^^^^^^^^^^^^^^^^^^^^^^^^^^^^^^^^^^^
  File "C:\Users\drakkka\python\Lib\asyncio\base_events.py", line 654, in run_until_complete
    return future.result()
           ^^^^^^^^^^^^^^^
  File "C:\Users\drakkka\Documents\tuber stuff\aigohere\zwaif\z-waif-main\z-waif main new\utils\vtube_studio.py", line 102, in emote
    await VTS.connect()
  File "C:\Users\drakkka\Documents\tuber stuff\aigohere\zwaif\z-waif-main\z-waif main new\venv\Lib\site-packages\pyvts\vts.py", line 82, in connect
    self.websocket = await websockets.connect(
                     ^^^^^^^^^^^^^^^^^^^^^^^^^
  File "C:\Users\drakkka\Documents\tuber stuff\aigohere\zwaif\z-waif-main\z-waif main new\venv\Lib\site-packages\websockets\legacy\client.py", line 655, in __await_impl_timeout__
    return await self.__await_impl__()
           ^^^^^^^^^^^^^^^^^^^^^^^^^^^
  File "C:\Users\drakkka\Documents\tuber stuff\aigohere\zwaif\z-waif-main\z-waif main new\venv\Lib\site-packages\websockets\legacy\client.py", line 659, in __await_impl__
    _transport, _protocol = await self._create_connection()
                            ^^^^^^^^^^^^^^^^^^^^^^^^^^^^^^^
  File "C:\Users\drakkka\python\Lib\asyncio\base_events.py", line 1091, in create_connection
    raise exceptions[0]
  File "C:\Users\drakkka\python\Lib\asyncio\base_events.py", line 1070, in create_connection
    sock = await self._connect_sock(
           ^^^^^^^^^^^^^^^^^^^^^^^^^
  File "C:\Users\drakkka\python\Lib\asyncio\base_events.py", line 974, in _connect_sock
    await self.sock_connect(sock, address)
  File "C:\Users\drakkka\python\Lib\asyncio\proactor_events.py", line 726, in sock_connect
    return await self._proactor.connect(sock, address)
           ^^^^^^^^^^^^^^^^^^^^^^^^^^^^^^^^^^^^^^^^^^^
  File "C:\Users\drakkka\python\Lib\asyncio\windows_events.py", line 854, in _poll
    value = callback(transferred, key, ov)
            ^^^^^^^^^^^^^^^^^^^^^^^^^^^^^^
  File "C:\Users\drakkka\python\Lib\asyncio\windows_events.py", line 641, in finish_connect
    ov.getresult()
ConnectionRefusedError: [WinError 1225] The remote computer refused the network connection
Exception in thread Thread-63 (check_emote_string):
Traceback (most recent call last):
  File "C:\Users\drakkka\python\Lib\threading.py", line 1045, in _bootstrap_inner
    self.run()
  File "C:\Users\drakkka\python\Lib\threading.py", line 982, in run
    self._target(*self._args, **self._kwargs)
  File "C:\Users\drakkka\Documents\tuber stuff\aigohere\zwaif\z-waif-main\z-waif main new\utils\vtube_studio.py", line 95, in check_emote_string
    run_emote()
  File "C:\Users\drakkka\Documents\tuber stuff\aigohere\zwaif\z-waif-main\z-waif main new\utils\vtube_studio.py", line 99, in run_emote
    asyncio.run(emote())
  File "C:\Users\drakkka\python\Lib\asyncio\runners.py", line 190, in run
    return runner.run(main)
           ^^^^^^^^^^^^^^^^
  File "C:\Users\drakkka\python\Lib\asyncio\runners.py", line 118, in run
    return self._loop.run_until_complete(task)
           ^^^^^^^^^^^^^^^^^^^^^^^^^^^^^^^^^^^
  File "C:\Users\drakkka\python\Lib\asyncio\base_events.py", line 654, in run_until_complete
    return future.result()
           ^^^^^^^^^^^^^^^
  File "C:\Users\drakkka\Documents\tuber stuff\aigohere\zwaif\z-waif-main\z-waif main new\utils\vtube_studio.py", line 102, in emote
    await VTS.connect()
  File "C:\Users\drakkka\Documents\tuber stuff\aigohere\zwaif\z-waif-main\z-waif main new\venv\Lib\site-packages\pyvts\vts.py", line 82, in connect
    self.websocket = await websockets.connect(
                     ^^^^^^^^^^^^^^^^^^^^^^^^^
  File "C:\Users\drakkka\Documents\tuber stuff\aigohere\zwaif\z-waif-main\z-waif main new\venv\Lib\site-packages\websockets\legacy\client.py", line 655, in __await_impl_timeout__
    return await self.__await_impl__()
           ^^^^^^^^^^^^^^^^^^^^^^^^^^^
  File "C:\Users\drakkka\Documents\tuber stuff\aigohere\zwaif\z-waif-main\z-waif main new\venv\Lib\site-packages\websockets\legacy\client.py", line 659, in __await_impl__
    _transport, _protocol = await self._create_connection()
                            ^^^^^^^^^^^^^^^^^^^^^^^^^^^^^^^
  File "C:\Users\drakkka\python\Lib\asyncio\base_events.py", line 1091, in create_connection
    raise exceptions[0]
  File "C:\Users\drakkka\python\Lib\asyncio\base_events.py", line 1070, in create_connection
    sock = await self._connect_sock(
           ^^^^^^^^^^^^^^^^^^^^^^^^^
  File "C:\Users\drakkka\python\Lib\asyncio\base_events.py", line 974, in _connect_sock
    await self.sock_connect(sock, address)
  File "C:\Users\drakkka\python\Lib\asyncio\proactor_events.py", line 726, in sock_connect
    return await self._proactor.connect(sock, address)
           ^^^^^^^^^^^^^^^^^^^^^^^^^^^^^^^^^^^^^^^^^^^
  File "C:\Users\drakkka\python\Lib\asyncio\windows_events.py", line 854, in _poll
    value = callback(transferred, key, ov)
            ^^^^^^^^^^^^^^^^^^^^^^^^^^^^^^
  File "C:\Users\drakkka\python\Lib\asyncio\windows_events.py", line 641, in finish_connect
    ov.getresult()
ConnectionRefusedError: [WinError 1225] The remote computer refused the network connection
[2024-11-06 16:27:20] [INFO    ] discord.gateway: Shard ID None has successfully RESUMED session acc67a4ae758563efce1fd28cd015f8b.
  Running command git clone --filter=blob:none --quiet https://github.com/openai/whisper.git 'C:\Users\drakkka\AppData\Local\Temp\pip-req-build-izbiexsa'

[notice] A new release of pip is available: 24.0 -> 24.3.1
[notice] To update, run: python.exe -m pip install --upgrade pip

[notice] A new release of pip is available: 24.0 -> 24.3.1
[notice] To update, run: python.exe -m pip install --upgrade pip
[2024-11-15 20:16:47] [INFO    ] discord.client: logging in using static token
[2024-11-15 20:16:49] [INFO    ] discord.gateway: Shard ID None has connected to Gateway (Session ID: f806c367272494356cd863b419526f29).
Exception in thread Thread-6 (run_vtube_studio_connection):
Traceback (most recent call last):
  File "C:\Users\drakkka\python\Lib\threading.py", line 1045, in _bootstrap_inner
    self.run()
  File "C:\Users\drakkka\python\Lib\threading.py", line 982, in run
    self._target(*self._args, **self._kwargs)
  File "C:\Users\drakkka\Documents\tuber stuff\aigohere\zwaif\z-waif-main\experimental\snapshot\z-waif main new\utils\vtube_studio.py", line 50, in run_vtube_studio_connection
    asyncio.run(vtube_studio_connection())
  File "C:\Users\drakkka\python\Lib\asyncio\runners.py", line 190, in run
    return runner.run(main)
           ^^^^^^^^^^^^^^^^
  File "C:\Users\drakkka\python\Lib\asyncio\runners.py", line 118, in run
    return self._loop.run_until_complete(task)
           ^^^^^^^^^^^^^^^^^^^^^^^^^^^^^^^^^^^
  File "C:\Users\drakkka\python\Lib\asyncio\base_events.py", line 654, in run_until_complete
    return future.result()
           ^^^^^^^^^^^^^^^
  File "C:\Users\drakkka\Documents\tuber stuff\aigohere\zwaif\z-waif-main\experimental\snapshot\z-waif main new\utils\vtube_studio.py", line 53, in vtube_studio_connection
    await VTS.connect()
  File "C:\Users\drakkka\Documents\tuber stuff\aigohere\zwaif\z-waif-main\experimental\snapshot\z-waif main new\venv\Lib\site-packages\pyvts\vts.py", line 82, in connect
    self.websocket = await websockets.connect(
                     ^^^^^^^^^^^^^^^^^^^^^^^^^
  File "C:\Users\drakkka\Documents\tuber stuff\aigohere\zwaif\z-waif-main\experimental\snapshot\z-waif main new\venv\Lib\site-packages\websockets\legacy\client.py", line 655, in __await_impl_timeout__
    return await self.__await_impl__()
           ^^^^^^^^^^^^^^^^^^^^^^^^^^^
  File "C:\Users\drakkka\Documents\tuber stuff\aigohere\zwaif\z-waif-main\experimental\snapshot\z-waif main new\venv\Lib\site-packages\websockets\legacy\client.py", line 659, in __await_impl__
    _transport, _protocol = await self._create_connection()
                            ^^^^^^^^^^^^^^^^^^^^^^^^^^^^^^^
  File "C:\Users\drakkka\python\Lib\asyncio\base_events.py", line 1091, in create_connection
    raise exceptions[0]
  File "C:\Users\drakkka\python\Lib\asyncio\base_events.py", line 1070, in create_connection
    sock = await self._connect_sock(
           ^^^^^^^^^^^^^^^^^^^^^^^^^
  File "C:\Users\drakkka\python\Lib\asyncio\base_events.py", line 974, in _connect_sock
    await self.sock_connect(sock, address)
  File "C:\Users\drakkka\python\Lib\asyncio\proactor_events.py", line 726, in sock_connect
    return await self._proactor.connect(sock, address)
           ^^^^^^^^^^^^^^^^^^^^^^^^^^^^^^^^^^^^^^^^^^^
  File "C:\Users\drakkka\python\Lib\asyncio\windows_events.py", line 854, in _poll
    value = callback(transferred, key, ov)
            ^^^^^^^^^^^^^^^^^^^^^^^^^^^^^^
  File "C:\Users\drakkka\python\Lib\asyncio\windows_events.py", line 641, in finish_connect
    ov.getresult()
ConnectionRefusedError: [WinError 1225] The remote computer refused the network connection
[2024-11-15 20:21:59] [INFO    ] discord.client: logging in using static token
[2024-11-15 20:22:00] [INFO    ] discord.gateway: Shard ID None has connected to Gateway (Session ID: c70d573a35b2342a058b2bd925f8fa9e).
Exception in thread Thread-6 (run_vtube_studio_connection):
Traceback (most recent call last):
  File "C:\Users\drakkka\python\Lib\threading.py", line 1045, in _bootstrap_inner
    self.run()
  File "C:\Users\drakkka\python\Lib\threading.py", line 982, in run
    self._target(*self._args, **self._kwargs)
  File "C:\Users\drakkka\Documents\tuber stuff\aigohere\zwaif\z-waif-main\experimental\snapshot\z-waif main new\utils\vtube_studio.py", line 50, in run_vtube_studio_connection
    asyncio.run(vtube_studio_connection())
  File "C:\Users\drakkka\python\Lib\asyncio\runners.py", line 190, in run
    return runner.run(main)
           ^^^^^^^^^^^^^^^^
  File "C:\Users\drakkka\python\Lib\asyncio\runners.py", line 118, in run
    return self._loop.run_until_complete(task)
           ^^^^^^^^^^^^^^^^^^^^^^^^^^^^^^^^^^^
  File "C:\Users\drakkka\python\Lib\asyncio\base_events.py", line 654, in run_until_complete
    return future.result()
           ^^^^^^^^^^^^^^^
  File "C:\Users\drakkka\Documents\tuber stuff\aigohere\zwaif\z-waif-main\experimental\snapshot\z-waif main new\utils\vtube_studio.py", line 53, in vtube_studio_connection
    await VTS.connect()
  File "C:\Users\drakkka\Documents\tuber stuff\aigohere\zwaif\z-waif-main\experimental\snapshot\z-waif main new\venv\Lib\site-packages\pyvts\vts.py", line 82, in connect
    self.websocket = await websockets.connect(
                     ^^^^^^^^^^^^^^^^^^^^^^^^^
  File "C:\Users\drakkka\Documents\tuber stuff\aigohere\zwaif\z-waif-main\experimental\snapshot\z-waif main new\venv\Lib\site-packages\websockets\legacy\client.py", line 655, in __await_impl_timeout__
    return await self.__await_impl__()
           ^^^^^^^^^^^^^^^^^^^^^^^^^^^
  File "C:\Users\drakkka\Documents\tuber stuff\aigohere\zwaif\z-waif-main\experimental\snapshot\z-waif main new\venv\Lib\site-packages\websockets\legacy\client.py", line 659, in __await_impl__
    _transport, _protocol = await self._create_connection()
                            ^^^^^^^^^^^^^^^^^^^^^^^^^^^^^^^
  File "C:\Users\drakkka\python\Lib\asyncio\base_events.py", line 1091, in create_connection
    raise exceptions[0]
  File "C:\Users\drakkka\python\Lib\asyncio\base_events.py", line 1070, in create_connection
    sock = await self._connect_sock(
           ^^^^^^^^^^^^^^^^^^^^^^^^^
  File "C:\Users\drakkka\python\Lib\asyncio\base_events.py", line 974, in _connect_sock
    await self.sock_connect(sock, address)
  File "C:\Users\drakkka\python\Lib\asyncio\proactor_events.py", line 726, in sock_connect
    return await self._proactor.connect(sock, address)
           ^^^^^^^^^^^^^^^^^^^^^^^^^^^^^^^^^^^^^^^^^^^
  File "C:\Users\drakkka\python\Lib\asyncio\windows_events.py", line 854, in _poll
    value = callback(transferred, key, ov)
            ^^^^^^^^^^^^^^^^^^^^^^^^^^^^^^
  File "C:\Users\drakkka\python\Lib\asyncio\windows_events.py", line 641, in finish_connect
    ov.getresult()
ConnectionRefusedError: [WinError 1225] The remote computer refused the network connection
[2024-11-15 20:29:16] [INFO    ] discord.client: logging in using static token
[2024-11-15 20:29:17] [INFO    ] discord.gateway: Shard ID None has connected to Gateway (Session ID: d72886d5cb0f96a3d84f3e5e03baa4de).
Exception in thread Thread-6 (run_vtube_studio_connection):
Traceback (most recent call last):
  File "C:\Users\drakkka\python\Lib\threading.py", line 1045, in _bootstrap_inner
    self.run()
  File "C:\Users\drakkka\python\Lib\threading.py", line 982, in run
    self._target(*self._args, **self._kwargs)
  File "C:\Users\drakkka\Documents\tuber stuff\aigohere\zwaif\z-waif-main\experimental\snapshot\z-waif main new\utils\vtube_studio.py", line 50, in run_vtube_studio_connection
    asyncio.run(vtube_studio_connection())
  File "C:\Users\drakkka\python\Lib\asyncio\runners.py", line 190, in run
    return runner.run(main)
           ^^^^^^^^^^^^^^^^
  File "C:\Users\drakkka\python\Lib\asyncio\runners.py", line 118, in run
    return self._loop.run_until_complete(task)
           ^^^^^^^^^^^^^^^^^^^^^^^^^^^^^^^^^^^
  File "C:\Users\drakkka\python\Lib\asyncio\base_events.py", line 654, in run_until_complete
    return future.result()
           ^^^^^^^^^^^^^^^
  File "C:\Users\drakkka\Documents\tuber stuff\aigohere\zwaif\z-waif-main\experimental\snapshot\z-waif main new\utils\vtube_studio.py", line 53, in vtube_studio_connection
    await VTS.connect()
  File "C:\Users\drakkka\Documents\tuber stuff\aigohere\zwaif\z-waif-main\experimental\snapshot\z-waif main new\venv\Lib\site-packages\pyvts\vts.py", line 82, in connect
    self.websocket = await websockets.connect(
                     ^^^^^^^^^^^^^^^^^^^^^^^^^
  File "C:\Users\drakkka\Documents\tuber stuff\aigohere\zwaif\z-waif-main\experimental\snapshot\z-waif main new\venv\Lib\site-packages\websockets\legacy\client.py", line 655, in __await_impl_timeout__
    return await self.__await_impl__()
           ^^^^^^^^^^^^^^^^^^^^^^^^^^^
  File "C:\Users\drakkka\Documents\tuber stuff\aigohere\zwaif\z-waif-main\experimental\snapshot\z-waif main new\venv\Lib\site-packages\websockets\legacy\client.py", line 659, in __await_impl__
    _transport, _protocol = await self._create_connection()
                            ^^^^^^^^^^^^^^^^^^^^^^^^^^^^^^^
  File "C:\Users\drakkka\python\Lib\asyncio\base_events.py", line 1091, in create_connection
    raise exceptions[0]
  File "C:\Users\drakkka\python\Lib\asyncio\base_events.py", line 1070, in create_connection
    sock = await self._connect_sock(
           ^^^^^^^^^^^^^^^^^^^^^^^^^
  File "C:\Users\drakkka\python\Lib\asyncio\base_events.py", line 974, in _connect_sock
    await self.sock_connect(sock, address)
  File "C:\Users\drakkka\python\Lib\asyncio\proactor_events.py", line 726, in sock_connect
    return await self._proactor.connect(sock, address)
           ^^^^^^^^^^^^^^^^^^^^^^^^^^^^^^^^^^^^^^^^^^^
  File "C:\Users\drakkka\python\Lib\asyncio\windows_events.py", line 854, in _poll
    value = callback(transferred, key, ov)
            ^^^^^^^^^^^^^^^^^^^^^^^^^^^^^^
  File "C:\Users\drakkka\python\Lib\asyncio\windows_events.py", line 641, in finish_connect
    ov.getresult()
ConnectionRefusedError: [WinError 1225] The remote computer refused the network connection
[2024-11-15 20:31:05] [INFO    ] discord.client: logging in using static token
[2024-11-15 20:31:06] [INFO    ] discord.gateway: Shard ID None has connected to Gateway (Session ID: b429535c788e7972663f1749911ffb05).
Exception in thread Thread-6 (run_vtube_studio_connection):
Traceback (most recent call last):
  File "C:\Users\drakkka\python\Lib\threading.py", line 1045, in _bootstrap_inner
    self.run()
  File "C:\Users\drakkka\python\Lib\threading.py", line 982, in run
    self._target(*self._args, **self._kwargs)
  File "C:\Users\drakkka\Documents\tuber stuff\aigohere\zwaif\z-waif-main\experimental\snapshot\z-waif main new\utils\vtube_studio.py", line 50, in run_vtube_studio_connection
    asyncio.run(vtube_studio_connection())
  File "C:\Users\drakkka\python\Lib\asyncio\runners.py", line 190, in run
    return runner.run(main)
           ^^^^^^^^^^^^^^^^
  File "C:\Users\drakkka\python\Lib\asyncio\runners.py", line 118, in run
    return self._loop.run_until_complete(task)
           ^^^^^^^^^^^^^^^^^^^^^^^^^^^^^^^^^^^
  File "C:\Users\drakkka\python\Lib\asyncio\base_events.py", line 654, in run_until_complete
    return future.result()
           ^^^^^^^^^^^^^^^
  File "C:\Users\drakkka\Documents\tuber stuff\aigohere\zwaif\z-waif-main\experimental\snapshot\z-waif main new\utils\vtube_studio.py", line 53, in vtube_studio_connection
    await VTS.connect()
  File "C:\Users\drakkka\Documents\tuber stuff\aigohere\zwaif\z-waif-main\experimental\snapshot\z-waif main new\venv\Lib\site-packages\pyvts\vts.py", line 82, in connect
    self.websocket = await websockets.connect(
                     ^^^^^^^^^^^^^^^^^^^^^^^^^
  File "C:\Users\drakkka\Documents\tuber stuff\aigohere\zwaif\z-waif-main\experimental\snapshot\z-waif main new\venv\Lib\site-packages\websockets\legacy\client.py", line 655, in __await_impl_timeout__
    return await self.__await_impl__()
           ^^^^^^^^^^^^^^^^^^^^^^^^^^^
  File "C:\Users\drakkka\Documents\tuber stuff\aigohere\zwaif\z-waif-main\experimental\snapshot\z-waif main new\venv\Lib\site-packages\websockets\legacy\client.py", line 659, in __await_impl__
    _transport, _protocol = await self._create_connection()
                            ^^^^^^^^^^^^^^^^^^^^^^^^^^^^^^^
  File "C:\Users\drakkka\python\Lib\asyncio\base_events.py", line 1091, in create_connection
    raise exceptions[0]
  File "C:\Users\drakkka\python\Lib\asyncio\base_events.py", line 1070, in create_connection
    sock = await self._connect_sock(
           ^^^^^^^^^^^^^^^^^^^^^^^^^
  File "C:\Users\drakkka\python\Lib\asyncio\base_events.py", line 974, in _connect_sock
    await self.sock_connect(sock, address)
  File "C:\Users\drakkka\python\Lib\asyncio\proactor_events.py", line 726, in sock_connect
    return await self._proactor.connect(sock, address)
           ^^^^^^^^^^^^^^^^^^^^^^^^^^^^^^^^^^^^^^^^^^^
  File "C:\Users\drakkka\python\Lib\asyncio\windows_events.py", line 854, in _poll
    value = callback(transferred, key, ov)
            ^^^^^^^^^^^^^^^^^^^^^^^^^^^^^^
  File "C:\Users\drakkka\python\Lib\asyncio\windows_events.py", line 641, in finish_connect
    ov.getresult()
ConnectionRefusedError: [WinError 1225] The remote computer refused the network connection
[2024-11-15 20:32:40] [INFO    ] discord.client: logging in using static token
[2024-11-15 20:32:41] [INFO    ] discord.gateway: Shard ID None has connected to Gateway (Session ID: 9c2ca5e3ecd7e34f7b0605dbad16c750).
Exception in thread Thread-6 (run_vtube_studio_connection):
Traceback (most recent call last):
  File "C:\Users\drakkka\python\Lib\threading.py", line 1045, in _bootstrap_inner
    self.run()
  File "C:\Users\drakkka\python\Lib\threading.py", line 982, in run
    self._target(*self._args, **self._kwargs)
  File "C:\Users\drakkka\Documents\tuber stuff\aigohere\zwaif\z-waif-main\experimental\snapshot\z-waif main new\utils\vtube_studio.py", line 50, in run_vtube_studio_connection
    asyncio.run(vtube_studio_connection())
  File "C:\Users\drakkka\python\Lib\asyncio\runners.py", line 190, in run
    return runner.run(main)
           ^^^^^^^^^^^^^^^^
  File "C:\Users\drakkka\python\Lib\asyncio\runners.py", line 118, in run
    return self._loop.run_until_complete(task)
           ^^^^^^^^^^^^^^^^^^^^^^^^^^^^^^^^^^^
  File "C:\Users\drakkka\python\Lib\asyncio\base_events.py", line 654, in run_until_complete
    return future.result()
           ^^^^^^^^^^^^^^^
  File "C:\Users\drakkka\Documents\tuber stuff\aigohere\zwaif\z-waif-main\experimental\snapshot\z-waif main new\utils\vtube_studio.py", line 53, in vtube_studio_connection
    await VTS.connect()
  File "C:\Users\drakkka\Documents\tuber stuff\aigohere\zwaif\z-waif-main\experimental\snapshot\z-waif main new\venv\Lib\site-packages\pyvts\vts.py", line 82, in connect
    self.websocket = await websockets.connect(
                     ^^^^^^^^^^^^^^^^^^^^^^^^^
  File "C:\Users\drakkka\Documents\tuber stuff\aigohere\zwaif\z-waif-main\experimental\snapshot\z-waif main new\venv\Lib\site-packages\websockets\legacy\client.py", line 655, in __await_impl_timeout__
    return await self.__await_impl__()
           ^^^^^^^^^^^^^^^^^^^^^^^^^^^
  File "C:\Users\drakkka\Documents\tuber stuff\aigohere\zwaif\z-waif-main\experimental\snapshot\z-waif main new\venv\Lib\site-packages\websockets\legacy\client.py", line 659, in __await_impl__
    _transport, _protocol = await self._create_connection()
                            ^^^^^^^^^^^^^^^^^^^^^^^^^^^^^^^
  File "C:\Users\drakkka\python\Lib\asyncio\base_events.py", line 1091, in create_connection
    raise exceptions[0]
  File "C:\Users\drakkka\python\Lib\asyncio\base_events.py", line 1070, in create_connection
    sock = await self._connect_sock(
           ^^^^^^^^^^^^^^^^^^^^^^^^^
  File "C:\Users\drakkka\python\Lib\asyncio\base_events.py", line 974, in _connect_sock
    await self.sock_connect(sock, address)
  File "C:\Users\drakkka\python\Lib\asyncio\proactor_events.py", line 726, in sock_connect
    return await self._proactor.connect(sock, address)
           ^^^^^^^^^^^^^^^^^^^^^^^^^^^^^^^^^^^^^^^^^^^
  File "C:\Users\drakkka\python\Lib\asyncio\windows_events.py", line 854, in _poll
    value = callback(transferred, key, ov)
            ^^^^^^^^^^^^^^^^^^^^^^^^^^^^^^
  File "C:\Users\drakkka\python\Lib\asyncio\windows_events.py", line 641, in finish_connect
    ov.getresult()
ConnectionRefusedError: [WinError 1225] The remote computer refused the network connection
[2024-11-15 20:35:00] [INFO    ] discord.client: logging in using static token
Exception in thread Thread-12 (run_twitch_bot):
Traceback (most recent call last):
  File "C:\Users\drakkka\python\Lib\threading.py", line 1045, in _bootstrap_inner
    self.run()
  File "C:\Users\drakkka\python\Lib\threading.py", line 982, in run
    self._target(*self._args, **self._kwargs)
  File "C:\Users\drakkka\Documents\tuber stuff\aigohere\zwaif\z-waif-main\experimental\snapshot\z-waif main new\utils\z_waif_twitch.py", line 77, in run_twitch_bot
    bot = Bot()
          ^^^^^
  File "C:\Users\drakkka\Documents\tuber stuff\aigohere\zwaif\z-waif-main\experimental\snapshot\z-waif main new\utils\z_waif_twitch.py", line 38, in __init__
    super().__init__(
  File "C:\Users\drakkka\Documents\tuber stuff\aigohere\zwaif\z-waif-main\experimental\snapshot\z-waif main new\venv\Lib\site-packages\twitchio\ext\commands\bot.py", line 61, in __init__
    super().__init__(
  File "C:\Users\drakkka\Documents\tuber stuff\aigohere\zwaif\z-waif-main\experimental\snapshot\z-waif main new\venv\Lib\site-packages\twitchio\client.py", line 84, in __init__
    self.loop: asyncio.AbstractEventLoop = loop or asyncio.get_event_loop()
                                                   ^^^^^^^^^^^^^^^^^^^^^^^^
  File "C:\Users\drakkka\python\Lib\asyncio\events.py", line 681, in get_event_loop
    raise RuntimeError('There is no current event loop in thread %r.'
RuntimeError: There is no current event loop in thread 'Thread-12 (run_twitch_bot)'.
[2024-11-15 20:35:01] [INFO    ] discord.gateway: Shard ID None has connected to Gateway (Session ID: 2fe3909c218838961849a9cbcc40a4e8).
Exception in thread Thread-6 (run_vtube_studio_connection):
Traceback (most recent call last):
  File "C:\Users\drakkka\python\Lib\threading.py", line 1045, in _bootstrap_inner
    self.run()
  File "C:\Users\drakkka\python\Lib\threading.py", line 982, in run
    self._target(*self._args, **self._kwargs)
  File "C:\Users\drakkka\Documents\tuber stuff\aigohere\zwaif\z-waif-main\experimental\snapshot\z-waif main new\utils\vtube_studio.py", line 50, in run_vtube_studio_connection
    asyncio.run(vtube_studio_connection())
  File "C:\Users\drakkka\python\Lib\asyncio\runners.py", line 190, in run
    return runner.run(main)
           ^^^^^^^^^^^^^^^^
  File "C:\Users\drakkka\python\Lib\asyncio\runners.py", line 118, in run
    return self._loop.run_until_complete(task)
           ^^^^^^^^^^^^^^^^^^^^^^^^^^^^^^^^^^^
  File "C:\Users\drakkka\python\Lib\asyncio\base_events.py", line 654, in run_until_complete
    return future.result()
           ^^^^^^^^^^^^^^^
  File "C:\Users\drakkka\Documents\tuber stuff\aigohere\zwaif\z-waif-main\experimental\snapshot\z-waif main new\utils\vtube_studio.py", line 53, in vtube_studio_connection
    await VTS.connect()
  File "C:\Users\drakkka\Documents\tuber stuff\aigohere\zwaif\z-waif-main\experimental\snapshot\z-waif main new\venv\Lib\site-packages\pyvts\vts.py", line 82, in connect
    self.websocket = await websockets.connect(
                     ^^^^^^^^^^^^^^^^^^^^^^^^^
  File "C:\Users\drakkka\Documents\tuber stuff\aigohere\zwaif\z-waif-main\experimental\snapshot\z-waif main new\venv\Lib\site-packages\websockets\legacy\client.py", line 655, in __await_impl_timeout__
    return await self.__await_impl__()
           ^^^^^^^^^^^^^^^^^^^^^^^^^^^
  File "C:\Users\drakkka\Documents\tuber stuff\aigohere\zwaif\z-waif-main\experimental\snapshot\z-waif main new\venv\Lib\site-packages\websockets\legacy\client.py", line 659, in __await_impl__
    _transport, _protocol = await self._create_connection()
                            ^^^^^^^^^^^^^^^^^^^^^^^^^^^^^^^
  File "C:\Users\drakkka\python\Lib\asyncio\base_events.py", line 1091, in create_connection
    raise exceptions[0]
  File "C:\Users\drakkka\python\Lib\asyncio\base_events.py", line 1070, in create_connection
    sock = await self._connect_sock(
           ^^^^^^^^^^^^^^^^^^^^^^^^^
  File "C:\Users\drakkka\python\Lib\asyncio\base_events.py", line 974, in _connect_sock
    await self.sock_connect(sock, address)
  File "C:\Users\drakkka\python\Lib\asyncio\proactor_events.py", line 726, in sock_connect
    return await self._proactor.connect(sock, address)
           ^^^^^^^^^^^^^^^^^^^^^^^^^^^^^^^^^^^^^^^^^^^
  File "C:\Users\drakkka\python\Lib\asyncio\windows_events.py", line 854, in _poll
    value = callback(transferred, key, ov)
            ^^^^^^^^^^^^^^^^^^^^^^^^^^^^^^
  File "C:\Users\drakkka\python\Lib\asyncio\windows_events.py", line 641, in finish_connect
    ov.getresult()
ConnectionRefusedError: [WinError 1225] The remote computer refused the network connection
[2024-11-15 20:37:51] [INFO    ] discord.client: logging in using static token
[2024-11-15 20:37:53] [INFO    ] discord.gateway: Shard ID None has connected to Gateway (Session ID: 970d67824cf547fb890f5f1f4dedf614).
Exception in thread Thread-6 (run_vtube_studio_connection):
Traceback (most recent call last):
  File "C:\Users\drakkka\python\Lib\threading.py", line 1045, in _bootstrap_inner
    self.run()
  File "C:\Users\drakkka\python\Lib\threading.py", line 982, in run
    self._target(*self._args, **self._kwargs)
  File "C:\Users\drakkka\Documents\tuber stuff\aigohere\zwaif\z-waif-main\experimental\snapshot\z-waif main new\utils\vtube_studio.py", line 50, in run_vtube_studio_connection
    asyncio.run(vtube_studio_connection())
  File "C:\Users\drakkka\python\Lib\asyncio\runners.py", line 190, in run
    return runner.run(main)
           ^^^^^^^^^^^^^^^^
  File "C:\Users\drakkka\python\Lib\asyncio\runners.py", line 118, in run
    return self._loop.run_until_complete(task)
           ^^^^^^^^^^^^^^^^^^^^^^^^^^^^^^^^^^^
  File "C:\Users\drakkka\python\Lib\asyncio\base_events.py", line 654, in run_until_complete
    return future.result()
           ^^^^^^^^^^^^^^^
  File "C:\Users\drakkka\Documents\tuber stuff\aigohere\zwaif\z-waif-main\experimental\snapshot\z-waif main new\utils\vtube_studio.py", line 53, in vtube_studio_connection
    await VTS.connect()
  File "C:\Users\drakkka\Documents\tuber stuff\aigohere\zwaif\z-waif-main\experimental\snapshot\z-waif main new\venv\Lib\site-packages\pyvts\vts.py", line 82, in connect
    self.websocket = await websockets.connect(
                     ^^^^^^^^^^^^^^^^^^^^^^^^^
  File "C:\Users\drakkka\Documents\tuber stuff\aigohere\zwaif\z-waif-main\experimental\snapshot\z-waif main new\venv\Lib\site-packages\websockets\legacy\client.py", line 655, in __await_impl_timeout__
    return await self.__await_impl__()
           ^^^^^^^^^^^^^^^^^^^^^^^^^^^
  File "C:\Users\drakkka\Documents\tuber stuff\aigohere\zwaif\z-waif-main\experimental\snapshot\z-waif main new\venv\Lib\site-packages\websockets\legacy\client.py", line 659, in __await_impl__
    _transport, _protocol = await self._create_connection()
                            ^^^^^^^^^^^^^^^^^^^^^^^^^^^^^^^
  File "C:\Users\drakkka\python\Lib\asyncio\base_events.py", line 1091, in create_connection
    raise exceptions[0]
  File "C:\Users\drakkka\python\Lib\asyncio\base_events.py", line 1070, in create_connection
    sock = await self._connect_sock(
           ^^^^^^^^^^^^^^^^^^^^^^^^^
  File "C:\Users\drakkka\python\Lib\asyncio\base_events.py", line 974, in _connect_sock
    await self.sock_connect(sock, address)
  File "C:\Users\drakkka\python\Lib\asyncio\proactor_events.py", line 726, in sock_connect
    return await self._proactor.connect(sock, address)
           ^^^^^^^^^^^^^^^^^^^^^^^^^^^^^^^^^^^^^^^^^^^
  File "C:\Users\drakkka\python\Lib\asyncio\windows_events.py", line 854, in _poll
    value = callback(transferred, key, ov)
            ^^^^^^^^^^^^^^^^^^^^^^^^^^^^^^
  File "C:\Users\drakkka\python\Lib\asyncio\windows_events.py", line 641, in finish_connect
    ov.getresult()
ConnectionRefusedError: [WinError 1225] The remote computer refused the network connection
[2024-11-15 20:40:03] [INFO    ] discord.client: logging in using static token
[2024-11-15 20:40:04] [INFO    ] discord.gateway: Shard ID None has connected to Gateway (Session ID: 2126eb0801563cea178bf35475cbc2c5).
Traceback (most recent call last):
  File "C:\Users\drakkka\Documents\tuber stuff\aigohere\zwaif\z-waif-main\experimental\snapshot\z-waif main new\venv\Lib\site-packages\twitchio\client.py", line 208, in wrapped
    await func(*args)
  File "C:\Users\drakkka\Documents\tuber stuff\aigohere\zwaif\z-waif-main\experimental\snapshot\z-waif main new\utils\z_waif_twitch.py", line 35, in event_ready
    print(f"Connected to channels: {[chan for chan in self.initial_channels]}")
                                                      ^^^^^^^^^^^^^^^^^^^^^
AttributeError: 'Bot' object has no attribute 'initial_channels'
Exception in thread Thread-6 (run_vtube_studio_connection):
Traceback (most recent call last):
  File "C:\Users\drakkka\python\Lib\threading.py", line 1045, in _bootstrap_inner
    self.run()
  File "C:\Users\drakkka\python\Lib\threading.py", line 982, in run
    self._target(*self._args, **self._kwargs)
  File "C:\Users\drakkka\Documents\tuber stuff\aigohere\zwaif\z-waif-main\experimental\snapshot\z-waif main new\utils\vtube_studio.py", line 50, in run_vtube_studio_connection
    asyncio.run(vtube_studio_connection())
  File "C:\Users\drakkka\python\Lib\asyncio\runners.py", line 190, in run
    return runner.run(main)
           ^^^^^^^^^^^^^^^^
  File "C:\Users\drakkka\python\Lib\asyncio\runners.py", line 118, in run
    return self._loop.run_until_complete(task)
           ^^^^^^^^^^^^^^^^^^^^^^^^^^^^^^^^^^^
  File "C:\Users\drakkka\python\Lib\asyncio\base_events.py", line 654, in run_until_complete
    return future.result()
           ^^^^^^^^^^^^^^^
  File "C:\Users\drakkka\Documents\tuber stuff\aigohere\zwaif\z-waif-main\experimental\snapshot\z-waif main new\utils\vtube_studio.py", line 53, in vtube_studio_connection
    await VTS.connect()
  File "C:\Users\drakkka\Documents\tuber stuff\aigohere\zwaif\z-waif-main\experimental\snapshot\z-waif main new\venv\Lib\site-packages\pyvts\vts.py", line 82, in connect
    self.websocket = await websockets.connect(
                     ^^^^^^^^^^^^^^^^^^^^^^^^^
  File "C:\Users\drakkka\Documents\tuber stuff\aigohere\zwaif\z-waif-main\experimental\snapshot\z-waif main new\venv\Lib\site-packages\websockets\legacy\client.py", line 655, in __await_impl_timeout__
    return await self.__await_impl__()
           ^^^^^^^^^^^^^^^^^^^^^^^^^^^
  File "C:\Users\drakkka\Documents\tuber stuff\aigohere\zwaif\z-waif-main\experimental\snapshot\z-waif main new\venv\Lib\site-packages\websockets\legacy\client.py", line 659, in __await_impl__
    _transport, _protocol = await self._create_connection()
                            ^^^^^^^^^^^^^^^^^^^^^^^^^^^^^^^
  File "C:\Users\drakkka\python\Lib\asyncio\base_events.py", line 1091, in create_connection
    raise exceptions[0]
  File "C:\Users\drakkka\python\Lib\asyncio\base_events.py", line 1070, in create_connection
    sock = await self._connect_sock(
           ^^^^^^^^^^^^^^^^^^^^^^^^^
  File "C:\Users\drakkka\python\Lib\asyncio\base_events.py", line 974, in _connect_sock
    await self.sock_connect(sock, address)
  File "C:\Users\drakkka\python\Lib\asyncio\proactor_events.py", line 726, in sock_connect
    return await self._proactor.connect(sock, address)
           ^^^^^^^^^^^^^^^^^^^^^^^^^^^^^^^^^^^^^^^^^^^
  File "C:\Users\drakkka\python\Lib\asyncio\windows_events.py", line 854, in _poll
    value = callback(transferred, key, ov)
            ^^^^^^^^^^^^^^^^^^^^^^^^^^^^^^
  File "C:\Users\drakkka\python\Lib\asyncio\windows_events.py", line 641, in finish_connect
    ov.getresult()
ConnectionRefusedError: [WinError 1225] The remote computer refused the network connection
[2024-11-15 20:41:28] [INFO    ] discord.client: logging in using static token
[2024-11-15 20:41:30] [INFO    ] discord.gateway: Shard ID None has connected to Gateway (Session ID: 22775f1b6c338f9d59d22aa9305b74cf).
Exception in thread Thread-6 (run_vtube_studio_connection):
Traceback (most recent call last):
  File "C:\Users\drakkka\python\Lib\threading.py", line 1045, in _bootstrap_inner
    self.run()
  File "C:\Users\drakkka\python\Lib\threading.py", line 982, in run
    self._target(*self._args, **self._kwargs)
  File "C:\Users\drakkka\Documents\tuber stuff\aigohere\zwaif\z-waif-main\experimental\snapshot\z-waif main new\utils\vtube_studio.py", line 50, in run_vtube_studio_connection
    asyncio.run(vtube_studio_connection())
  File "C:\Users\drakkka\python\Lib\asyncio\runners.py", line 190, in run
    return runner.run(main)
           ^^^^^^^^^^^^^^^^
  File "C:\Users\drakkka\python\Lib\asyncio\runners.py", line 118, in run
    return self._loop.run_until_complete(task)
           ^^^^^^^^^^^^^^^^^^^^^^^^^^^^^^^^^^^
  File "C:\Users\drakkka\python\Lib\asyncio\base_events.py", line 654, in run_until_complete
    return future.result()
           ^^^^^^^^^^^^^^^
  File "C:\Users\drakkka\Documents\tuber stuff\aigohere\zwaif\z-waif-main\experimental\snapshot\z-waif main new\utils\vtube_studio.py", line 53, in vtube_studio_connection
    await VTS.connect()
  File "C:\Users\drakkka\Documents\tuber stuff\aigohere\zwaif\z-waif-main\experimental\snapshot\z-waif main new\venv\Lib\site-packages\pyvts\vts.py", line 82, in connect
    self.websocket = await websockets.connect(
                     ^^^^^^^^^^^^^^^^^^^^^^^^^
  File "C:\Users\drakkka\Documents\tuber stuff\aigohere\zwaif\z-waif-main\experimental\snapshot\z-waif main new\venv\Lib\site-packages\websockets\legacy\client.py", line 655, in __await_impl_timeout__
    return await self.__await_impl__()
           ^^^^^^^^^^^^^^^^^^^^^^^^^^^
  File "C:\Users\drakkka\Documents\tuber stuff\aigohere\zwaif\z-waif-main\experimental\snapshot\z-waif main new\venv\Lib\site-packages\websockets\legacy\client.py", line 659, in __await_impl__
    _transport, _protocol = await self._create_connection()
                            ^^^^^^^^^^^^^^^^^^^^^^^^^^^^^^^
  File "C:\Users\drakkka\python\Lib\asyncio\base_events.py", line 1091, in create_connection
    raise exceptions[0]
  File "C:\Users\drakkka\python\Lib\asyncio\base_events.py", line 1070, in create_connection
    sock = await self._connect_sock(
           ^^^^^^^^^^^^^^^^^^^^^^^^^
  File "C:\Users\drakkka\python\Lib\asyncio\base_events.py", line 974, in _connect_sock
    await self.sock_connect(sock, address)
  File "C:\Users\drakkka\python\Lib\asyncio\proactor_events.py", line 726, in sock_connect
    return await self._proactor.connect(sock, address)
           ^^^^^^^^^^^^^^^^^^^^^^^^^^^^^^^^^^^^^^^^^^^
  File "C:\Users\drakkka\python\Lib\asyncio\windows_events.py", line 854, in _poll
    value = callback(transferred, key, ov)
            ^^^^^^^^^^^^^^^^^^^^^^^^^^^^^^
  File "C:\Users\drakkka\python\Lib\asyncio\windows_events.py", line 641, in finish_connect
    ov.getresult()
ConnectionRefusedError: [WinError 1225] The remote computer refused the network connection
[2024-11-15 20:46:08] [INFO    ] discord.client: logging in using static token
[2024-11-15 20:46:10] [INFO    ] discord.gateway: Shard ID None has connected to Gateway (Session ID: 03217503440dd7921c377ed9c9bf2673).
Exception in thread Thread-6 (run_vtube_studio_connection):
Traceback (most recent call last):
  File "C:\Users\drakkka\python\Lib\threading.py", line 1045, in _bootstrap_inner
    self.run()
  File "C:\Users\drakkka\python\Lib\threading.py", line 982, in run
    self._target(*self._args, **self._kwargs)
  File "C:\Users\drakkka\Documents\tuber stuff\aigohere\zwaif\z-waif-main\experimental\snapshot\z-waif main new\utils\vtube_studio.py", line 50, in run_vtube_studio_connection
    asyncio.run(vtube_studio_connection())
  File "C:\Users\drakkka\python\Lib\asyncio\runners.py", line 190, in run
    return runner.run(main)
           ^^^^^^^^^^^^^^^^
  File "C:\Users\drakkka\python\Lib\asyncio\runners.py", line 118, in run
    return self._loop.run_until_complete(task)
           ^^^^^^^^^^^^^^^^^^^^^^^^^^^^^^^^^^^
  File "C:\Users\drakkka\python\Lib\asyncio\base_events.py", line 654, in run_until_complete
    return future.result()
           ^^^^^^^^^^^^^^^
  File "C:\Users\drakkka\Documents\tuber stuff\aigohere\zwaif\z-waif-main\experimental\snapshot\z-waif main new\utils\vtube_studio.py", line 53, in vtube_studio_connection
    await VTS.connect()
  File "C:\Users\drakkka\Documents\tuber stuff\aigohere\zwaif\z-waif-main\experimental\snapshot\z-waif main new\venv\Lib\site-packages\pyvts\vts.py", line 82, in connect
    self.websocket = await websockets.connect(
                     ^^^^^^^^^^^^^^^^^^^^^^^^^
  File "C:\Users\drakkka\Documents\tuber stuff\aigohere\zwaif\z-waif-main\experimental\snapshot\z-waif main new\venv\Lib\site-packages\websockets\legacy\client.py", line 655, in __await_impl_timeout__
    return await self.__await_impl__()
           ^^^^^^^^^^^^^^^^^^^^^^^^^^^
  File "C:\Users\drakkka\Documents\tuber stuff\aigohere\zwaif\z-waif-main\experimental\snapshot\z-waif main new\venv\Lib\site-packages\websockets\legacy\client.py", line 659, in __await_impl__
    _transport, _protocol = await self._create_connection()
                            ^^^^^^^^^^^^^^^^^^^^^^^^^^^^^^^
  File "C:\Users\drakkka\python\Lib\asyncio\base_events.py", line 1091, in create_connection
    raise exceptions[0]
  File "C:\Users\drakkka\python\Lib\asyncio\base_events.py", line 1070, in create_connection
    sock = await self._connect_sock(
           ^^^^^^^^^^^^^^^^^^^^^^^^^
  File "C:\Users\drakkka\python\Lib\asyncio\base_events.py", line 974, in _connect_sock
    await self.sock_connect(sock, address)
  File "C:\Users\drakkka\python\Lib\asyncio\proactor_events.py", line 726, in sock_connect
    return await self._proactor.connect(sock, address)
           ^^^^^^^^^^^^^^^^^^^^^^^^^^^^^^^^^^^^^^^^^^^
  File "C:\Users\drakkka\python\Lib\asyncio\windows_events.py", line 854, in _poll
    value = callback(transferred, key, ov)
            ^^^^^^^^^^^^^^^^^^^^^^^^^^^^^^
  File "C:\Users\drakkka\python\Lib\asyncio\windows_events.py", line 641, in finish_connect
    ov.getresult()
ConnectionRefusedError: [WinError 1225] The remote computer refused the network connection
[2024-11-15 20:49:28] [INFO    ] discord.client: logging in using static token
[2024-11-15 20:49:29] [INFO    ] discord.gateway: Shard ID None has connected to Gateway (Session ID: 1f1f0dd32b177fe30996d47b9f1b0cc2).
Exception in thread Thread-6 (run_vtube_studio_connection):
Traceback (most recent call last):
  File "C:\Users\drakkka\python\Lib\threading.py", line 1045, in _bootstrap_inner
    self.run()
  File "C:\Users\drakkka\python\Lib\threading.py", line 982, in run
    self._target(*self._args, **self._kwargs)
  File "C:\Users\drakkka\Documents\tuber stuff\aigohere\zwaif\z-waif-main\experimental\snapshot\z-waif main new\utils\vtube_studio.py", line 50, in run_vtube_studio_connection
    asyncio.run(vtube_studio_connection())
  File "C:\Users\drakkka\python\Lib\asyncio\runners.py", line 190, in run
    return runner.run(main)
           ^^^^^^^^^^^^^^^^
  File "C:\Users\drakkka\python\Lib\asyncio\runners.py", line 118, in run
    return self._loop.run_until_complete(task)
           ^^^^^^^^^^^^^^^^^^^^^^^^^^^^^^^^^^^
  File "C:\Users\drakkka\python\Lib\asyncio\base_events.py", line 654, in run_until_complete
    return future.result()
           ^^^^^^^^^^^^^^^
  File "C:\Users\drakkka\Documents\tuber stuff\aigohere\zwaif\z-waif-main\experimental\snapshot\z-waif main new\utils\vtube_studio.py", line 53, in vtube_studio_connection
    await VTS.connect()
  File "C:\Users\drakkka\Documents\tuber stuff\aigohere\zwaif\z-waif-main\experimental\snapshot\z-waif main new\venv\Lib\site-packages\pyvts\vts.py", line 82, in connect
    self.websocket = await websockets.connect(
                     ^^^^^^^^^^^^^^^^^^^^^^^^^
  File "C:\Users\drakkka\Documents\tuber stuff\aigohere\zwaif\z-waif-main\experimental\snapshot\z-waif main new\venv\Lib\site-packages\websockets\legacy\client.py", line 655, in __await_impl_timeout__
    return await self.__await_impl__()
           ^^^^^^^^^^^^^^^^^^^^^^^^^^^
  File "C:\Users\drakkka\Documents\tuber stuff\aigohere\zwaif\z-waif-main\experimental\snapshot\z-waif main new\venv\Lib\site-packages\websockets\legacy\client.py", line 659, in __await_impl__
    _transport, _protocol = await self._create_connection()
                            ^^^^^^^^^^^^^^^^^^^^^^^^^^^^^^^
  File "C:\Users\drakkka\python\Lib\asyncio\base_events.py", line 1091, in create_connection
    raise exceptions[0]
  File "C:\Users\drakkka\python\Lib\asyncio\base_events.py", line 1070, in create_connection
    sock = await self._connect_sock(
           ^^^^^^^^^^^^^^^^^^^^^^^^^
  File "C:\Users\drakkka\python\Lib\asyncio\base_events.py", line 974, in _connect_sock
    await self.sock_connect(sock, address)
  File "C:\Users\drakkka\python\Lib\asyncio\proactor_events.py", line 726, in sock_connect
    return await self._proactor.connect(sock, address)
           ^^^^^^^^^^^^^^^^^^^^^^^^^^^^^^^^^^^^^^^^^^^
  File "C:\Users\drakkka\python\Lib\asyncio\windows_events.py", line 854, in _poll
    value = callback(transferred, key, ov)
            ^^^^^^^^^^^^^^^^^^^^^^^^^^^^^^
  File "C:\Users\drakkka\python\Lib\asyncio\windows_events.py", line 641, in finish_connect
    ov.getresult()
ConnectionRefusedError: [WinError 1225] The remote computer refused the network connection
[2024-11-15 20:54:43] [INFO    ] discord.client: logging in using static token
[2024-11-15 20:54:45] [INFO    ] discord.gateway: Shard ID None has connected to Gateway (Session ID: 3d3b234853cd1ddd1cc8b0cc08f19dbd).
Exception in thread Thread-6 (run_vtube_studio_connection):
Traceback (most recent call last):
  File "C:\Users\drakkka\python\Lib\threading.py", line 1045, in _bootstrap_inner
    self.run()
  File "C:\Users\drakkka\python\Lib\threading.py", line 982, in run
    self._target(*self._args, **self._kwargs)
  File "C:\Users\drakkka\Documents\tuber stuff\aigohere\zwaif\z-waif-main\experimental\snapshot\z-waif main new\utils\vtube_studio.py", line 50, in run_vtube_studio_connection
    asyncio.run(vtube_studio_connection())
  File "C:\Users\drakkka\python\Lib\asyncio\runners.py", line 190, in run
    return runner.run(main)
           ^^^^^^^^^^^^^^^^
  File "C:\Users\drakkka\python\Lib\asyncio\runners.py", line 118, in run
    return self._loop.run_until_complete(task)
           ^^^^^^^^^^^^^^^^^^^^^^^^^^^^^^^^^^^
  File "C:\Users\drakkka\python\Lib\asyncio\base_events.py", line 654, in run_until_complete
    return future.result()
           ^^^^^^^^^^^^^^^
  File "C:\Users\drakkka\Documents\tuber stuff\aigohere\zwaif\z-waif-main\experimental\snapshot\z-waif main new\utils\vtube_studio.py", line 53, in vtube_studio_connection
    await VTS.connect()
  File "C:\Users\drakkka\Documents\tuber stuff\aigohere\zwaif\z-waif-main\experimental\snapshot\z-waif main new\venv\Lib\site-packages\pyvts\vts.py", line 82, in connect
    self.websocket = await websockets.connect(
                     ^^^^^^^^^^^^^^^^^^^^^^^^^
  File "C:\Users\drakkka\Documents\tuber stuff\aigohere\zwaif\z-waif-main\experimental\snapshot\z-waif main new\venv\Lib\site-packages\websockets\legacy\client.py", line 655, in __await_impl_timeout__
    return await self.__await_impl__()
           ^^^^^^^^^^^^^^^^^^^^^^^^^^^
  File "C:\Users\drakkka\Documents\tuber stuff\aigohere\zwaif\z-waif-main\experimental\snapshot\z-waif main new\venv\Lib\site-packages\websockets\legacy\client.py", line 659, in __await_impl__
    _transport, _protocol = await self._create_connection()
                            ^^^^^^^^^^^^^^^^^^^^^^^^^^^^^^^
  File "C:\Users\drakkka\python\Lib\asyncio\base_events.py", line 1091, in create_connection
    raise exceptions[0]
  File "C:\Users\drakkka\python\Lib\asyncio\base_events.py", line 1070, in create_connection
    sock = await self._connect_sock(
           ^^^^^^^^^^^^^^^^^^^^^^^^^
  File "C:\Users\drakkka\python\Lib\asyncio\base_events.py", line 974, in _connect_sock
    await self.sock_connect(sock, address)
  File "C:\Users\drakkka\python\Lib\asyncio\proactor_events.py", line 726, in sock_connect
    return await self._proactor.connect(sock, address)
           ^^^^^^^^^^^^^^^^^^^^^^^^^^^^^^^^^^^^^^^^^^^
  File "C:\Users\drakkka\python\Lib\asyncio\windows_events.py", line 854, in _poll
    value = callback(transferred, key, ov)
            ^^^^^^^^^^^^^^^^^^^^^^^^^^^^^^
  File "C:\Users\drakkka\python\Lib\asyncio\windows_events.py", line 641, in finish_connect
    ov.getresult()
ConnectionRefusedError: [WinError 1225] The remote computer refused the network connection
[2024-11-15 20:57:12] [INFO    ] discord.client: logging in using static token
[2024-11-15 20:57:13] [INFO    ] discord.gateway: Shard ID None has connected to Gateway (Session ID: d3253fab11e5b3952d605aa7decacd24).
Exception in thread Thread-6 (run_vtube_studio_connection):
Traceback (most recent call last):
  File "C:\Users\drakkka\python\Lib\threading.py", line 1045, in _bootstrap_inner
    self.run()
  File "C:\Users\drakkka\python\Lib\threading.py", line 982, in run
    self._target(*self._args, **self._kwargs)
  File "C:\Users\drakkka\Documents\tuber stuff\aigohere\zwaif\z-waif-main\experimental\snapshot\z-waif main new\utils\vtube_studio.py", line 50, in run_vtube_studio_connection
    asyncio.run(vtube_studio_connection())
  File "C:\Users\drakkka\python\Lib\asyncio\runners.py", line 190, in run
    return runner.run(main)
           ^^^^^^^^^^^^^^^^
  File "C:\Users\drakkka\python\Lib\asyncio\runners.py", line 118, in run
    return self._loop.run_until_complete(task)
           ^^^^^^^^^^^^^^^^^^^^^^^^^^^^^^^^^^^
  File "C:\Users\drakkka\python\Lib\asyncio\base_events.py", line 654, in run_until_complete
    return future.result()
           ^^^^^^^^^^^^^^^
  File "C:\Users\drakkka\Documents\tuber stuff\aigohere\zwaif\z-waif-main\experimental\snapshot\z-waif main new\utils\vtube_studio.py", line 53, in vtube_studio_connection
    await VTS.connect()
  File "C:\Users\drakkka\Documents\tuber stuff\aigohere\zwaif\z-waif-main\experimental\snapshot\z-waif main new\venv\Lib\site-packages\pyvts\vts.py", line 82, in connect
    self.websocket = await websockets.connect(
                     ^^^^^^^^^^^^^^^^^^^^^^^^^
  File "C:\Users\drakkka\Documents\tuber stuff\aigohere\zwaif\z-waif-main\experimental\snapshot\z-waif main new\venv\Lib\site-packages\websockets\legacy\client.py", line 655, in __await_impl_timeout__
    return await self.__await_impl__()
           ^^^^^^^^^^^^^^^^^^^^^^^^^^^
  File "C:\Users\drakkka\Documents\tuber stuff\aigohere\zwaif\z-waif-main\experimental\snapshot\z-waif main new\venv\Lib\site-packages\websockets\legacy\client.py", line 659, in __await_impl__
    _transport, _protocol = await self._create_connection()
                            ^^^^^^^^^^^^^^^^^^^^^^^^^^^^^^^
  File "C:\Users\drakkka\python\Lib\asyncio\base_events.py", line 1091, in create_connection
    raise exceptions[0]
  File "C:\Users\drakkka\python\Lib\asyncio\base_events.py", line 1070, in create_connection
    sock = await self._connect_sock(
           ^^^^^^^^^^^^^^^^^^^^^^^^^
  File "C:\Users\drakkka\python\Lib\asyncio\base_events.py", line 974, in _connect_sock
    await self.sock_connect(sock, address)
  File "C:\Users\drakkka\python\Lib\asyncio\proactor_events.py", line 726, in sock_connect
    return await self._proactor.connect(sock, address)
           ^^^^^^^^^^^^^^^^^^^^^^^^^^^^^^^^^^^^^^^^^^^
  File "C:\Users\drakkka\python\Lib\asyncio\windows_events.py", line 854, in _poll
    value = callback(transferred, key, ov)
            ^^^^^^^^^^^^^^^^^^^^^^^^^^^^^^
  File "C:\Users\drakkka\python\Lib\asyncio\windows_events.py", line 641, in finish_connect
    ov.getresult()
ConnectionRefusedError: [WinError 1225] The remote computer refused the network connection
Exception in thread Thread-17 (check_emote_string):
Traceback (most recent call last):
  File "C:\Users\drakkka\python\Lib\threading.py", line 1045, in _bootstrap_inner
    self.run()
  File "C:\Users\drakkka\python\Lib\threading.py", line 982, in run
    self._target(*self._args, **self._kwargs)
  File "C:\Users\drakkka\Documents\tuber stuff\aigohere\zwaif\z-waif-main\experimental\snapshot\z-waif main new\utils\vtube_studio.py", line 95, in check_emote_string
    run_emote()
  File "C:\Users\drakkka\Documents\tuber stuff\aigohere\zwaif\z-waif-main\experimental\snapshot\z-waif main new\utils\vtube_studio.py", line 99, in run_emote
    asyncio.run(emote())
  File "C:\Users\drakkka\python\Lib\asyncio\runners.py", line 190, in run
    return runner.run(main)
           ^^^^^^^^^^^^^^^^
  File "C:\Users\drakkka\python\Lib\asyncio\runners.py", line 118, in run
    return self._loop.run_until_complete(task)
           ^^^^^^^^^^^^^^^^^^^^^^^^^^^^^^^^^^^
  File "C:\Users\drakkka\python\Lib\asyncio\base_events.py", line 654, in run_until_complete
    return future.result()
           ^^^^^^^^^^^^^^^
  File "C:\Users\drakkka\Documents\tuber stuff\aigohere\zwaif\z-waif-main\experimental\snapshot\z-waif main new\utils\vtube_studio.py", line 102, in emote
    await VTS.connect()
  File "C:\Users\drakkka\Documents\tuber stuff\aigohere\zwaif\z-waif-main\experimental\snapshot\z-waif main new\venv\Lib\site-packages\pyvts\vts.py", line 82, in connect
    self.websocket = await websockets.connect(
                     ^^^^^^^^^^^^^^^^^^^^^^^^^
  File "C:\Users\drakkka\Documents\tuber stuff\aigohere\zwaif\z-waif-main\experimental\snapshot\z-waif main new\venv\Lib\site-packages\websockets\legacy\client.py", line 655, in __await_impl_timeout__
    return await self.__await_impl__()
           ^^^^^^^^^^^^^^^^^^^^^^^^^^^
  File "C:\Users\drakkka\Documents\tuber stuff\aigohere\zwaif\z-waif-main\experimental\snapshot\z-waif main new\venv\Lib\site-packages\websockets\legacy\client.py", line 659, in __await_impl__
    _transport, _protocol = await self._create_connection()
                            ^^^^^^^^^^^^^^^^^^^^^^^^^^^^^^^
  File "C:\Users\drakkka\python\Lib\asyncio\base_events.py", line 1091, in create_connection
    raise exceptions[0]
  File "C:\Users\drakkka\python\Lib\asyncio\base_events.py", line 1070, in create_connection
    sock = await self._connect_sock(
           ^^^^^^^^^^^^^^^^^^^^^^^^^
  File "C:\Users\drakkka\python\Lib\asyncio\base_events.py", line 974, in _connect_sock
    await self.sock_connect(sock, address)
  File "C:\Users\drakkka\python\Lib\asyncio\proactor_events.py", line 726, in sock_connect
    return await self._proactor.connect(sock, address)
           ^^^^^^^^^^^^^^^^^^^^^^^^^^^^^^^^^^^^^^^^^^^
  File "C:\Users\drakkka\python\Lib\asyncio\windows_events.py", line 854, in _poll
    value = callback(transferred, key, ov)
            ^^^^^^^^^^^^^^^^^^^^^^^^^^^^^^
  File "C:\Users\drakkka\python\Lib\asyncio\windows_events.py", line 641, in finish_connect
    ov.getresult()
ConnectionRefusedError: [WinError 1225] The remote computer refused the network connection
[2024-11-15 21:39:32] [INFO    ] discord.client: logging in using static token
[2024-11-15 21:39:33] [INFO    ] discord.gateway: Shard ID None has connected to Gateway (Session ID: f00767ec6c3f90157b6dbf53af1379ff).
Exception in thread Thread-6 (run_vtube_studio_connection):
Traceback (most recent call last):
  File "C:\Users\drakkka\python\Lib\threading.py", line 1045, in _bootstrap_inner
    self.run()
  File "C:\Users\drakkka\python\Lib\threading.py", line 982, in run
    self._target(*self._args, **self._kwargs)
  File "C:\Users\drakkka\Documents\tuber stuff\aigohere\zwaif\z-waif-main\experimental\snapshot\z-waif main new\utils\vtube_studio.py", line 50, in run_vtube_studio_connection
    asyncio.run(vtube_studio_connection())
  File "C:\Users\drakkka\python\Lib\asyncio\runners.py", line 190, in run
    return runner.run(main)
           ^^^^^^^^^^^^^^^^
  File "C:\Users\drakkka\python\Lib\asyncio\runners.py", line 118, in run
    return self._loop.run_until_complete(task)
           ^^^^^^^^^^^^^^^^^^^^^^^^^^^^^^^^^^^
  File "C:\Users\drakkka\python\Lib\asyncio\base_events.py", line 654, in run_until_complete
    return future.result()
           ^^^^^^^^^^^^^^^
  File "C:\Users\drakkka\Documents\tuber stuff\aigohere\zwaif\z-waif-main\experimental\snapshot\z-waif main new\utils\vtube_studio.py", line 53, in vtube_studio_connection
    await VTS.connect()
  File "C:\Users\drakkka\Documents\tuber stuff\aigohere\zwaif\z-waif-main\experimental\snapshot\z-waif main new\venv\Lib\site-packages\pyvts\vts.py", line 82, in connect
    self.websocket = await websockets.connect(
                     ^^^^^^^^^^^^^^^^^^^^^^^^^
  File "C:\Users\drakkka\Documents\tuber stuff\aigohere\zwaif\z-waif-main\experimental\snapshot\z-waif main new\venv\Lib\site-packages\websockets\legacy\client.py", line 655, in __await_impl_timeout__
    return await self.__await_impl__()
           ^^^^^^^^^^^^^^^^^^^^^^^^^^^
  File "C:\Users\drakkka\Documents\tuber stuff\aigohere\zwaif\z-waif-main\experimental\snapshot\z-waif main new\venv\Lib\site-packages\websockets\legacy\client.py", line 659, in __await_impl__
    _transport, _protocol = await self._create_connection()
                            ^^^^^^^^^^^^^^^^^^^^^^^^^^^^^^^
  File "C:\Users\drakkka\python\Lib\asyncio\base_events.py", line 1091, in create_connection
    raise exceptions[0]
  File "C:\Users\drakkka\python\Lib\asyncio\base_events.py", line 1070, in create_connection
    sock = await self._connect_sock(
           ^^^^^^^^^^^^^^^^^^^^^^^^^
  File "C:\Users\drakkka\python\Lib\asyncio\base_events.py", line 974, in _connect_sock
    await self.sock_connect(sock, address)
  File "C:\Users\drakkka\python\Lib\asyncio\proactor_events.py", line 726, in sock_connect
    return await self._proactor.connect(sock, address)
           ^^^^^^^^^^^^^^^^^^^^^^^^^^^^^^^^^^^^^^^^^^^
  File "C:\Users\drakkka\python\Lib\asyncio\windows_events.py", line 854, in _poll
    value = callback(transferred, key, ov)
            ^^^^^^^^^^^^^^^^^^^^^^^^^^^^^^
  File "C:\Users\drakkka\python\Lib\asyncio\windows_events.py", line 641, in finish_connect
    ov.getresult()
ConnectionRefusedError: [WinError 1225] The remote computer refused the network connection
[2024-11-15 21:51:29] [INFO    ] discord.client: logging in using static token
[2024-11-15 21:51:31] [INFO    ] discord.gateway: Shard ID None has connected to Gateway (Session ID: 3770ca683d0316914e643229733cc559).
Exception in thread Thread-6 (run_vtube_studio_connection):
Traceback (most recent call last):
  File "C:\Users\drakkka\python\Lib\threading.py", line 1045, in _bootstrap_inner
    self.run()
  File "C:\Users\drakkka\python\Lib\threading.py", line 982, in run
    self._target(*self._args, **self._kwargs)
  File "C:\Users\drakkka\Documents\tuber stuff\aigohere\zwaif\z-waif-main\experimental\snapshot\z-waif main new\utils\vtube_studio.py", line 50, in run_vtube_studio_connection
    asyncio.run(vtube_studio_connection())
  File "C:\Users\drakkka\python\Lib\asyncio\runners.py", line 190, in run
    return runner.run(main)
           ^^^^^^^^^^^^^^^^
  File "C:\Users\drakkka\python\Lib\asyncio\runners.py", line 118, in run
    return self._loop.run_until_complete(task)
           ^^^^^^^^^^^^^^^^^^^^^^^^^^^^^^^^^^^
  File "C:\Users\drakkka\python\Lib\asyncio\base_events.py", line 654, in run_until_complete
    return future.result()
           ^^^^^^^^^^^^^^^
  File "C:\Users\drakkka\Documents\tuber stuff\aigohere\zwaif\z-waif-main\experimental\snapshot\z-waif main new\utils\vtube_studio.py", line 53, in vtube_studio_connection
    await VTS.connect()
  File "C:\Users\drakkka\Documents\tuber stuff\aigohere\zwaif\z-waif-main\experimental\snapshot\z-waif main new\venv\Lib\site-packages\pyvts\vts.py", line 82, in connect
    self.websocket = await websockets.connect(
                     ^^^^^^^^^^^^^^^^^^^^^^^^^
  File "C:\Users\drakkka\Documents\tuber stuff\aigohere\zwaif\z-waif-main\experimental\snapshot\z-waif main new\venv\Lib\site-packages\websockets\legacy\client.py", line 655, in __await_impl_timeout__
    return await self.__await_impl__()
           ^^^^^^^^^^^^^^^^^^^^^^^^^^^
  File "C:\Users\drakkka\Documents\tuber stuff\aigohere\zwaif\z-waif-main\experimental\snapshot\z-waif main new\venv\Lib\site-packages\websockets\legacy\client.py", line 659, in __await_impl__
    _transport, _protocol = await self._create_connection()
                            ^^^^^^^^^^^^^^^^^^^^^^^^^^^^^^^
  File "C:\Users\drakkka\python\Lib\asyncio\base_events.py", line 1091, in create_connection
    raise exceptions[0]
  File "C:\Users\drakkka\python\Lib\asyncio\base_events.py", line 1070, in create_connection
    sock = await self._connect_sock(
           ^^^^^^^^^^^^^^^^^^^^^^^^^
  File "C:\Users\drakkka\python\Lib\asyncio\base_events.py", line 974, in _connect_sock
    await self.sock_connect(sock, address)
  File "C:\Users\drakkka\python\Lib\asyncio\proactor_events.py", line 726, in sock_connect
    return await self._proactor.connect(sock, address)
           ^^^^^^^^^^^^^^^^^^^^^^^^^^^^^^^^^^^^^^^^^^^
  File "C:\Users\drakkka\python\Lib\asyncio\windows_events.py", line 854, in _poll
    value = callback(transferred, key, ov)
            ^^^^^^^^^^^^^^^^^^^^^^^^^^^^^^
  File "C:\Users\drakkka\python\Lib\asyncio\windows_events.py", line 641, in finish_connect
    ov.getresult()
ConnectionRefusedError: [WinError 1225] The remote computer refused the network connection
[2024-11-15 22:10:34] [INFO    ] discord.gateway: Shard ID None has successfully RESUMED session 3770ca683d0316914e643229733cc559.
[2024-11-15 23:08:47] [INFO    ] discord.client: logging in using static token
[2024-11-15 23:08:49] [INFO    ] discord.gateway: Shard ID None has connected to Gateway (Session ID: 63a3af46bc79a20c28d326b083ed8dc8).
Exception in thread Thread-6 (run_vtube_studio_connection):
Traceback (most recent call last):
  File "C:\Users\drakkka\python\Lib\threading.py", line 1045, in _bootstrap_inner
    self.run()
  File "C:\Users\drakkka\python\Lib\threading.py", line 982, in run
    self._target(*self._args, **self._kwargs)
  File "C:\Users\drakkka\Documents\tuber stuff\aigohere\zwaif\z-waif-main\experimental\stable builds\fixed bugs\z-waif main new\utils\vtube_studio.py", line 50, in run_vtube_studio_connection
    asyncio.run(vtube_studio_connection())
  File "C:\Users\drakkka\python\Lib\asyncio\runners.py", line 190, in run
    return runner.run(main)
           ^^^^^^^^^^^^^^^^
  File "C:\Users\drakkka\python\Lib\asyncio\runners.py", line 118, in run
    return self._loop.run_until_complete(task)
           ^^^^^^^^^^^^^^^^^^^^^^^^^^^^^^^^^^^
  File "C:\Users\drakkka\python\Lib\asyncio\base_events.py", line 654, in run_until_complete
    return future.result()
           ^^^^^^^^^^^^^^^
  File "C:\Users\drakkka\Documents\tuber stuff\aigohere\zwaif\z-waif-main\experimental\stable builds\fixed bugs\z-waif main new\utils\vtube_studio.py", line 53, in vtube_studio_connection
    await VTS.connect()
  File "C:\Users\drakkka\Documents\tuber stuff\aigohere\zwaif\z-waif-main\experimental\stable builds\fixed bugs\z-waif main new\venv\Lib\site-packages\pyvts\vts.py", line 82, in connect
    self.websocket = await websockets.connect(
                     ^^^^^^^^^^^^^^^^^^^^^^^^^
  File "C:\Users\drakkka\Documents\tuber stuff\aigohere\zwaif\z-waif-main\experimental\stable builds\fixed bugs\z-waif main new\venv\Lib\site-packages\websockets\legacy\client.py", line 655, in __await_impl_timeout__
    return await self.__await_impl__()
           ^^^^^^^^^^^^^^^^^^^^^^^^^^^
  File "C:\Users\drakkka\Documents\tuber stuff\aigohere\zwaif\z-waif-main\experimental\stable builds\fixed bugs\z-waif main new\venv\Lib\site-packages\websockets\legacy\client.py", line 659, in __await_impl__
    _transport, _protocol = await self._create_connection()
                            ^^^^^^^^^^^^^^^^^^^^^^^^^^^^^^^
  File "C:\Users\drakkka\python\Lib\asyncio\base_events.py", line 1091, in create_connection
    raise exceptions[0]
  File "C:\Users\drakkka\python\Lib\asyncio\base_events.py", line 1070, in create_connection
    sock = await self._connect_sock(
           ^^^^^^^^^^^^^^^^^^^^^^^^^
  File "C:\Users\drakkka\python\Lib\asyncio\base_events.py", line 974, in _connect_sock
    await self.sock_connect(sock, address)
  File "C:\Users\drakkka\python\Lib\asyncio\proactor_events.py", line 726, in sock_connect
    return await self._proactor.connect(sock, address)
           ^^^^^^^^^^^^^^^^^^^^^^^^^^^^^^^^^^^^^^^^^^^
  File "C:\Users\drakkka\python\Lib\asyncio\windows_events.py", line 854, in _poll
    value = callback(transferred, key, ov)
            ^^^^^^^^^^^^^^^^^^^^^^^^^^^^^^
  File "C:\Users\drakkka\python\Lib\asyncio\windows_events.py", line 641, in finish_connect
    ov.getresult()
ConnectionRefusedError: [WinError 1225] The remote computer refused the network connection
^C[2024-11-15 23:21:10] [INFO    ] discord.client: logging in using static token
[2024-11-15 23:21:11] [INFO    ] discord.gateway: Shard ID None has connected to Gateway (Session ID: 1d44bb0c07c2f717dde825cf5869fe52).
Exception in thread Thread-6 (run_vtube_studio_connection):
Traceback (most recent call last):
  File "C:\Users\drakkka\python\Lib\threading.py", line 1045, in _bootstrap_inner
    self.run()
  File "C:\Users\drakkka\python\Lib\threading.py", line 982, in run
    self._target(*self._args, **self._kwargs)
  File "C:\Users\drakkka\Documents\tuber stuff\aigohere\zwaif\z-waif-main\experimental\stable builds\fixed bugs\z-waif main new\utils\vtube_studio.py", line 50, in run_vtube_studio_connection
    asyncio.run(vtube_studio_connection())
  File "C:\Users\drakkka\python\Lib\asyncio\runners.py", line 190, in run
    return runner.run(main)
           ^^^^^^^^^^^^^^^^
  File "C:\Users\drakkka\python\Lib\asyncio\runners.py", line 118, in run
    return self._loop.run_until_complete(task)
           ^^^^^^^^^^^^^^^^^^^^^^^^^^^^^^^^^^^
  File "C:\Users\drakkka\python\Lib\asyncio\base_events.py", line 654, in run_until_complete
    return future.result()
           ^^^^^^^^^^^^^^^
  File "C:\Users\drakkka\Documents\tuber stuff\aigohere\zwaif\z-waif-main\experimental\stable builds\fixed bugs\z-waif main new\utils\vtube_studio.py", line 53, in vtube_studio_connection
    await VTS.connect()
  File "C:\Users\drakkka\Documents\tuber stuff\aigohere\zwaif\z-waif-main\experimental\stable builds\fixed bugs\z-waif main new\venv\Lib\site-packages\pyvts\vts.py", line 82, in connect
    self.websocket = await websockets.connect(
                     ^^^^^^^^^^^^^^^^^^^^^^^^^
  File "C:\Users\drakkka\Documents\tuber stuff\aigohere\zwaif\z-waif-main\experimental\stable builds\fixed bugs\z-waif main new\venv\Lib\site-packages\websockets\legacy\client.py", line 655, in __await_impl_timeout__
    return await self.__await_impl__()
           ^^^^^^^^^^^^^^^^^^^^^^^^^^^
  File "C:\Users\drakkka\Documents\tuber stuff\aigohere\zwaif\z-waif-main\experimental\stable builds\fixed bugs\z-waif main new\venv\Lib\site-packages\websockets\legacy\client.py", line 659, in __await_impl__
    _transport, _protocol = await self._create_connection()
                            ^^^^^^^^^^^^^^^^^^^^^^^^^^^^^^^
  File "C:\Users\drakkka\python\Lib\asyncio\base_events.py", line 1091, in create_connection
    raise exceptions[0]
  File "C:\Users\drakkka\python\Lib\asyncio\base_events.py", line 1070, in create_connection
    sock = await self._connect_sock(
           ^^^^^^^^^^^^^^^^^^^^^^^^^
  File "C:\Users\drakkka\python\Lib\asyncio\base_events.py", line 974, in _connect_sock
    await self.sock_connect(sock, address)
  File "C:\Users\drakkka\python\Lib\asyncio\proactor_events.py", line 726, in sock_connect
    return await self._proactor.connect(sock, address)
           ^^^^^^^^^^^^^^^^^^^^^^^^^^^^^^^^^^^^^^^^^^^
  File "C:\Users\drakkka\python\Lib\asyncio\windows_events.py", line 854, in _poll
    value = callback(transferred, key, ov)
            ^^^^^^^^^^^^^^^^^^^^^^^^^^^^^^
  File "C:\Users\drakkka\python\Lib\asyncio\windows_events.py", line 641, in finish_connect
    ov.getresult()
ConnectionRefusedError: [WinError 1225] The remote computer refused the network connection
[2024-11-15 23:22:51] [ERROR   ] discord.client: Ignoring exception in on_message
Traceback (most recent call last):
  File "C:\Users\drakkka\Documents\tuber stuff\aigohere\zwaif\z-waif-main\experimental\stable builds\fixed bugs\z-waif main new\venv\Lib\site-packages\discord\client.py", line 449, in _run_event
    await coro(*args, **kwargs)
  File "C:\Users\drakkka\Documents\tuber stuff\aigohere\zwaif\z-waif-main\experimental\stable builds\fixed bugs\z-waif main new\utils\z_waif_discord.py", line 57, in on_message
    await message.channel.send(message_reply)
  File "C:\Users\drakkka\Documents\tuber stuff\aigohere\zwaif\z-waif-main\experimental\stable builds\fixed bugs\z-waif main new\venv\Lib\site-packages\discord\abc.py", line 1618, in send
    data = await state.http.send_message(channel.id, params=params)
           ^^^^^^^^^^^^^^^^^^^^^^^^^^^^^^^^^^^^^^^^^^^^^^^^^^^^^^^^
  File "C:\Users\drakkka\Documents\tuber stuff\aigohere\zwaif\z-waif-main\experimental\stable builds\fixed bugs\z-waif main new\venv\Lib\site-packages\discord\http.py", line 758, in request
    raise HTTPException(response, data)
discord.errors.HTTPException: 400 Bad Request (error code: 50006): Cannot send an empty message
Exception in thread Thread-17 (check_emote_string):
Traceback (most recent call last):
  File "C:\Users\drakkka\python\Lib\threading.py", line 1045, in _bootstrap_inner
    self.run()
  File "C:\Users\drakkka\python\Lib\threading.py", line 982, in run
    self._target(*self._args, **self._kwargs)
  File "C:\Users\drakkka\Documents\tuber stuff\aigohere\zwaif\z-waif-main\experimental\stable builds\fixed bugs\z-waif main new\utils\vtube_studio.py", line 95, in check_emote_string
    run_emote()
  File "C:\Users\drakkka\Documents\tuber stuff\aigohere\zwaif\z-waif-main\experimental\stable builds\fixed bugs\z-waif main new\utils\vtube_studio.py", line 99, in run_emote
    asyncio.run(emote())
  File "C:\Users\drakkka\python\Lib\asyncio\runners.py", line 190, in run
    return runner.run(main)
           ^^^^^^^^^^^^^^^^
  File "C:\Users\drakkka\python\Lib\asyncio\runners.py", line 118, in run
    return self._loop.run_until_complete(task)
           ^^^^^^^^^^^^^^^^^^^^^^^^^^^^^^^^^^^
  File "C:\Users\drakkka\python\Lib\asyncio\base_events.py", line 654, in run_until_complete
    return future.result()
           ^^^^^^^^^^^^^^^
  File "C:\Users\drakkka\Documents\tuber stuff\aigohere\zwaif\z-waif-main\experimental\stable builds\fixed bugs\z-waif main new\utils\vtube_studio.py", line 102, in emote
    await VTS.connect()
  File "C:\Users\drakkka\Documents\tuber stuff\aigohere\zwaif\z-waif-main\experimental\stable builds\fixed bugs\z-waif main new\venv\Lib\site-packages\pyvts\vts.py", line 82, in connect
    self.websocket = await websockets.connect(
                     ^^^^^^^^^^^^^^^^^^^^^^^^^
  File "C:\Users\drakkka\Documents\tuber stuff\aigohere\zwaif\z-waif-main\experimental\stable builds\fixed bugs\z-waif main new\venv\Lib\site-packages\websockets\legacy\client.py", line 655, in __await_impl_timeout__
    return await self.__await_impl__()
           ^^^^^^^^^^^^^^^^^^^^^^^^^^^
  File "C:\Users\drakkka\Documents\tuber stuff\aigohere\zwaif\z-waif-main\experimental\stable builds\fixed bugs\z-waif main new\venv\Lib\site-packages\websockets\legacy\client.py", line 659, in __await_impl__
    _transport, _protocol = await self._create_connection()
                            ^^^^^^^^^^^^^^^^^^^^^^^^^^^^^^^
  File "C:\Users\drakkka\python\Lib\asyncio\base_events.py", line 1091, in create_connection
    raise exceptions[0]
  File "C:\Users\drakkka\python\Lib\asyncio\base_events.py", line 1070, in create_connection
    sock = await self._connect_sock(
           ^^^^^^^^^^^^^^^^^^^^^^^^^
  File "C:\Users\drakkka\python\Lib\asyncio\base_events.py", line 974, in _connect_sock
    await self.sock_connect(sock, address)
  File "C:\Users\drakkka\python\Lib\asyncio\proactor_events.py", line 726, in sock_connect
    return await self._proactor.connect(sock, address)
           ^^^^^^^^^^^^^^^^^^^^^^^^^^^^^^^^^^^^^^^^^^^
  File "C:\Users\drakkka\python\Lib\asyncio\windows_events.py", line 854, in _poll
    value = callback(transferred, key, ov)
            ^^^^^^^^^^^^^^^^^^^^^^^^^^^^^^
  File "C:\Users\drakkka\python\Lib\asyncio\windows_events.py", line 641, in finish_connect
    ov.getresult()
ConnectionRefusedError: [WinError 1225] The remote computer refused the network connection
